Workbook

Sheet App Support
A1: Number | B1: Created | C1: Priority | D1: Status | E1: Channel | F1: Active | G1: Short Description | H1: Description | I1: Assignment Group | J1: Assigned to | K1: Action | L1: Parent | M1: Problem | N1: Caused by Change | O1: Location | P1: Resolution codes | Q1: Resolution notes | R1: Tags | S1: Module | T1: Type Of Issue | U1: Standard Type of Issue | V1: Action taken? | W1: Remarks
A2: INCTEC1613822 | B2: 46113.398 | C2: 4 - Low | D2: Closed | E2: Phone | F2: FALSE | G2: RACPAD | Receipt Reversal Failure | H2: Store number: 05569 Coworker name and ID: Tenika Davis (101141) Customer name and number: Brown Ellen (114943798) Issue description: Coworker is not able to reverse the receipt, getting "Failed to reverse the payment" error. Receipt No: 461702892 Steps taken to arrive at problem: Time of occurrence (Recreate the issue and notate the time if needed): Screen shot required: YES | I2: RACPad Support | J2: Lalit RameshTurkar | K2: RACPAD - Payment | M2: PRB0044395 | O2: 05569 - EMPORIA-MAIN - A - M0386 - R0007 - S08 - RACUSA | P2: Incident-App-DataFixDeployed | Q2: Dear user , As per the request we have reversed the receipt - 461702892 . Please check and confirm if we are good to resolve the incident . | S2: Payment | T2: Payment reversal | U2: =VLOOKUP(T2,'Standard Type of Issue'!$B$1:$C$332,2,0) -> Payment reversal
A3: INCTEC1614096 | B3: 46114.352 | C3: 4 - Low | D3: Closed | E3: Self Service | F3: FALSE | G3: RACPAD - Payment | Customer Refund | | H3: Customer Name: DARLEEN BROOKS Last 4 of Card Used: 6672 Exact Amount of Refund: 137.21 Exact Date of Refund: 04-01-2026 Agreement or Receipt #: 08252467838 Detailed Description of Issue: Took payment for a living room set that is being returned need to refund the money back on to the customers card. | I3: RACPad Support | J3: Sushmitha Sannidhi | K3: RACPAD - Payment | M3: PRB0044395 | O3: 04467 - DUNKIRK-4TH ST - A - M0417 - R0058 - S08 - RACUSA | P3: Incident-App-DataFixDeployed | Q3: Receipt # 461738829 is reversed from backend as per the request. For the reversed receipt, refund request is raised by treasury team for the overpayment collected in the amount of $ 397.72 as requested. Please allow up to 7-10 business days for the customer to receive funds back to the card . Reversed Receipt number: 461738829 Also, please refer the email sent for more details. | S3: Payment | T3: Payment reversal | U3: =VLOOKUP(T3,'Standard Type of Issue'!$B$1:$C$332,2,0) -> Payment reversal
A4: INCTEC1614099 | B4: 46114.359 | C4: 4 - Low | D4: Closed | E4: Self Service | F4: FALSE | G4: RACPAD - Payment | Reverse Payment | | H4: Good Morning, Alphonso Brown was never delivered and merchandise not received, Agreement was taken down in 11/09/24. Clubs have continued to charge through 02/14/2026. Please reverse these payments and refund customer from transactions dating from 10/22/2024-02/14/2026, As he should not have been charged. Please follow up with me As soon as possible if I need to submit a DM check or the refunds can be processed on the back end. Club Memeber ship ID# 100014595910 Agreement Number: 8170619055 Customer ID: 110840503 Customer Name: Alphonso Brown Date and Time Issue Was Occured: 2024-10-22 00:00:00 | I4: RACPad Support | J4: racha sahithya | K4: RACPAD - Payment | M4: PRB0044395 | O4: 05532 - LEESBURG-NORTH BLVD - A - M0132 - R0024 - S08 - RACUSA | P4: Request-Fulfilled | Q4: We have received a response from Business that we shouldn't reverse the 34 receipts mentioned. An agreement is not required to continue the RAC Benefits Plus membership. It is the customer's decision to stay a member or cancel their membership. If the District Manager reviews the account and a refund is determined to be owed. they should submit a check request for the amount of refund owed to the customer and send it to Accounts Payable. Store agreed to close the ticket. | S4: Payment | T4: Payment reversal | U4: =VLOOKUP(T4,'Standard Type of Issue'!$B$1:$C$332,2,0) -> Payment reversal
A5: INCTEC1614128 | B5: 46114.412 | C5: 4 - Low | D5: Closed | E5: Self Service | F5: FALSE | G5: RACPAD - Agreement | Loaner Agreement | | H5: cannot return loaner agreement Agreement Number: 8172324712 Customer ID: 906313 Customer Name: Christina McAlister Date and Time Issue Was Occured: 2026-04-02 09:53:20 Its a loaner agreement. While trying to return the agreement, its asking user to reverse the payment to void the agreement. There is no payment needed in loaner agreement as per CW | I5: RACPad Support | J5: Abhishek TV | K5: RACPAD - Agreement | M5: PRB0044395 | O5: 04059 - SPRINGFIELD-N. KANSAS - A - M0214 - R0080 - S08 - RACUSA | P5: Incident-App-DataFixDeployed | Q5: Steps taken for resolution: The agreement #8172324712 is updated to 'Void' and also updated the item #9999220877135 status to 'rent ready'. The end_date of the agreement inventory for the Agreement is also updated. Screenshots are attached for reference. Category: Agreement Void | S5: Payment | T5: Payment reversal | U5: =VLOOKUP(T5,'Standard Type of Issue'!$B$1:$C$332,2,0) -> Payment reversal
A6: INCTEC1614271 | B6: 46114.557 | C6: 4 - Low | D6: Closed | E6: Self Service | F6: FALSE | G6: RACPAD | Unable to Void Agreement | H6: eCommerce -Other - need this order cancelled please - Pending 8175023424 Richmond 72" Unfold Assembly - unable to void on my end. | I6: RACPad Support | J6: Pratik Singar | K6: RACPAD - Payment | M6: PRB0044395 | O6: 02982 - YELM AVENUE - A - M0329 - R0050 - S07 - RACUSA | P6: Incident-App-DataFixDeployed | Q6: Receipt 459773707 has been reversed and agreement 8175023424 voided. Received confirmation from store. Please refer attachment. | S6: Payment | T6: Payment reversal | U6: =VLOOKUP(T6,'Standard Type of Issue'!$B$1:$C$332,2,0) -> Payment reversal
A7: INCTEC1614337 | B7: 46114.628 | C7: 4 - Low | D7: Closed | E7: Self Service | F7: FALSE | G7: RACPAD - Payment | Customer Refund | | H7: Customer Name: TYLER ENGLEHART Customer ID : 5402772 Last 4 of Card Used: 2301 Exact Amount of Refund: $41.70 For 1 Amount is the Charge: $13.90 Exact Date of Refund: 02/03/2026, 03/11/2026, 04/01/2026 Agreement or Receipt #: 456336592, 459791400, 461716629 Detailed Description of Issue: Customer was being charged for BP after returning item and requests a refund for the last 3 payments on BP | I7: RACPad Support | J7: Rashmitha Shetty | K7: RACPAD - Payment | M7: PRB0044395 | O7: 03596 - HARTFORD CITY-JEFFERSON - A - M0177 - R0019 - S08 - RACUSA | P7: Incident-App-DataFixDeployed | Q7: As per the request we have reversed below receipts: Receipt: 456336592, 459791400, 461716629 Customer Name: TYLER ENGLEHART Customer ID: 5402772 Amount: $41.70(13.90 for each receipt) And treasury team has initiated the refund. We have informed store to allow up to 7-10 business days for the customer to receive funds back to the card used. category: Receipt Reversal. | R7: SR | S7: Payment | T7: Payment reversal | U7: =VLOOKUP(T7,'Standard Type of Issue'!$B$1:$C$332,2,0) -> Payment reversal
A8: INCTEC1614554 | B8: 46115.458 | C8: 4 - Low | D8: Resolved | E8: Phone | F8: TRUE | G8: RACPAD - Web order items not delivered but payments processed – unable to void agreement | H8: Store number: 02234 Coworker name and ID: Renee Rhoden (116316) Customer name and number: Janice Tubb (108233818) Issue description: Coworker called in reporting that a customer never received items from a web order, however payments continued to process successfully. Agreement # 8174655973 Item # 9999221979487 itme # 9999221448131 Screen shot required: YES | I8: RACPad Support | J8: racha sahithya | K8: RACPAD - Agreement | M8: PRB0044395 | O8: 02234 - HOU-34TH ST - A - M0051 - R0079 - S07 - RACUSA | P8: Incident-App-DataFixDeployed | Q8: Agreement #8174655973 has been voided from backend. | S8: Payment | T8: Payment reversal | U8: =VLOOKUP(T8,'Standard Type of Issue'!$B$1:$C$332,2,0) -> Payment reversal
A9: INCTEC1614580 | B9: 46115.484 | C9: 4 - Low | D9: Closed | E9: Self Service | F9: FALSE | G9: RACPAD - Payment | Unable to reverse the payment | | H9: trying to do a payment refund and Its not going to allow me to do it Agreement Number: 8174954887 Customer ID: 4596264 Hostname - 04474-HMLWV93 Customer Name: Brian Taft Date and Time Issue Was Occured: 2026-04-03 12:16:20 | I9: RACPad Support | J9: Rashmitha Shetty | K9: RACPAD - Payment | M9: PRB0044395 | O9: 04474 - BATH-WASHINGTON - A - M0476 - R0058 - S08 - RACUSA | P9: Incident-App-DataFixDeployed | Q9: As per the request, we have reversed below receipt: Receipt: 461895225 Customer Name: Brian Taft Customer ID : 4596264 Payment-method: Credit Payment Amount: $ 91.17 And Treasury team has initiated the refund for the same. Informed store to allow up to 7-10 business days for the customer to receive funds back to the card used. As request is completed resolving the incident category: Receipt reversal | R9: SR | S9: Payment | T9: Payment reversal | U9: =VLOOKUP(T9,'Standard Type of Issue'!$B$1:$C$332,2,0) -> Payment reversal
A10: INCTEC1614988 | B10: 46116.657 | C10: 4 - Low | D10: Closed | E10: Self Service | F10: FALSE | G10: RACPAD - Agreement | Agreement Void | | H10: customer never got item changed mind, we are unable to get account to void Agreement Number: 8174993651 Customer ID: 111788474 Customer Name: Amy Walkos Date and Time Issue Was Occured: 2026-04-04 15:35:52 | I10: RACPad Support | J10: Rashmitha Shetty | K10: RACPAD - Agreement | M10: PRB0044395 | O10: 02406 - MORGANTOWN - A - M0337 - R0058 - S08 - RACUSA | P10: Incident-App-DataFixDeployed | Q10: As per the request we have voided the Agreement Number: 8174993651 and updated associated item #"9999221909790" to rent ready. Received Store confirmation also, thus resolving the incident. category: Void Agreement | R10: SR | S10: Payment | T10: Payment reversal | U10: =VLOOKUP(T10,'Standard Type of Issue'!$B$1:$C$332,2,0) -> Payment reversal
A11: INCTEC1615503 | B11: 46118.597 | C11: 4 - Low | D11: Closed | E11: Self Service | F11: FALSE | G11: RACPAD - Payment | Customer Refund | | H11: Customer Name: Adam Drell Last 4 of Card Used: 0569 Exact Amount of Refund: 116.64 Exact Date of Refund: 04.01.26 Agreement or Receipt #: 8175216558 Detailed Description of Issue: Customer processed payment for special order & then another agreement was processed for in stock item & another payment was made. The customer no longer wants the special order item so we need to cancel & refund the amount he paid for on the special order. It will not allow us to refund that particular agreement only the last payment that was made. | I11: RACPad Support | J11: Pratik Singar | K11: RACPAD - Payment | M11: PRB0044395 | O11: 01871 - LAS VEGAS-TROPICANA - A - M0257 - R0050 - S07 - RACUSA | P11: Request-Fulfilled | Q11: After 3 strike not receied any updated from store, Hence resolving incident. | S11: Payment | T11: Payment reversal | U11: =VLOOKUP(T11,'Standard Type of Issue'!$B$1:$C$332,2,0) -> Payment reversal
A12: INCTEC1617278 | B12: 46123.61 | C12: 4 - Low | D12: Closed | E12: Self Service | F12: FALSE | G12: Racpad | H12: need help voiding a customer Customer Name : HARVEY JEFFERSON Customer ID : 110101914 Cust Name & ID : BERNI CEDENO - 740626 | I12: RACPad Support | J12: Lalit RameshTurkar | K12: RACPAD - Agreement | M12: PRB0044395 | O12: 03990 - LANTANA-LANTANA RD - A - M0155 - R0024 - S08 - RACUSA | P12: Incident-App-DataFixDeployed | Q12: Hi store , As per the store's request we have voided the agreement 8169481079- Harvey Jefferson 8170726072- Berni Cedeno .Please find the attached screenshot below for reference. As the receipt -390947881 is aged you can submit the check request for customer refund .Attached the process doc for check request. | S12: Payment | T12: Payment reversal | U12: =VLOOKUP(T12,'Standard Type of Issue'!$B$1:$C$332,2,0) -> Payment reversal
A13: INCTEC1622484 | B13: 46139.42 | C13: 4 - Low | D13: Resolved | E13: Self Service | F13: TRUE | G13: RACPAD - Payment | Customer Refund | | H13: Customer Name: Jajuan Carson Last 4 of Card Used: 7166 Exact Amount of Refund: $ 137.13 Exact Date of Refund: 04/16/2026 Agreement or Receipt #: 463186291 Detailed Description of Issue: Customer requesting refund for order that was cancelled before delivery. Racpad will not allow me to issue refund to customer | I13: RACPad Support | J13: Aditi Nayak | K13: RACPAD - Payment | M13: PRB0044395 | O13: 00346 - HAMPTON-MERCURY - A - M0007 - R0007 - S08 - RACUSA | P13: Incident-App-DataFixDeployed | Q13: Resolution steps: Reversed receipt 463186291, and the Treasury team has initiated a refund. Category: Receipt reversal | S13: Payment | T13: Payment reversal | U13: =VLOOKUP(T13,'Standard Type of Issue'!$B$1:$C$332,2,0) -> Payment reversal
A14: INCTEC1615973 | B14: 46119.681 | C14: 4 - Low | D14: Closed | E14: Self Service | F14: FALSE | G14: RACPAD - Payment | Customer Refund | | H14: Customer Name: Mohan Gupta Last 4 of Card Used: 7411 Exact Amount of Refund: 298.96 Exact Date of Refund: 4/7 Agreement or Receipt #: 462035391 Detailed Description of Issue: Customer need refund account dropped before payment ran | I14: RACPad Support | J14: Abhishek TV | K14: RACPAD - Payment | M14: PRB0044395 | O14: 00827 - BEAUFORT - A - M0001 - R0007 - S08 - RACUSA | P14: Incident-App-DataFixDeployed | Q14: Steps taken for resolution: Receipt #462035391 reversed and revenue recog also done. Treasury has requested a refund for the overpayment collected in the amount of $298.96 as requested: Please allow up to 7-10 business days for the customer to receive funds back to the card used. Category: Customer refund - receipt reversal | S14: Payment | T14: Payment reversal | U14: =VLOOKUP(T14,'Standard Type of Issue'!$B$1:$C$332,2,0) -> Payment reversal
A15: INCTEC1623367 | B15: 46141.475 | C15: 4 - Low | D15: Awaiting Change | E15: Self Service | F15: TRUE | G15: RACPAD - Payment | Customer Refund | | H15: Customer Name: Ted Lafortune Last 4 of Card Used: 1756 Exact Amount of Refund: $88.27 Exact Date of Refund: 4/28/26 Agreement or Receipt #: 464275887 Detailed Description of Issue: customer returned, same day ecomm pulled, need payment reversed! | I15: RACPad Support | J15: Lalit RameshTurkar | K15: RACPAD - Payment | M15: PRB0044395 | O15: 04678 - CLARKSVILLE-PROVIDENCE - A - M0488 - R0070 - S08 - RACUSA | S15: Payment | T15: Payment reversal | U15: =VLOOKUP(T15,'Standard Type of Issue'!$B$1:$C$332,2,0) -> Payment reversal
A16: INCTEC1616522 | B16: 46121.422 | C16: 4 - Low | D16: Closed | E16: Self Service | F16: FALSE | G16: RACPAD - Payment | Customer Refund | | H16: I am trying to give a customer back his refund because he canceled his agreement he processed online and will not allow me to do but the payment for his benefits plus not his other payment he processed. He paid $154.71 plus the monthly payment for benefits plus. Agreement Number: 8175248456 Customer ID: 3276828 Customer Name: Frank Fondi Date and Time Issue Was Occured: 2026-04-09 00:00:00 | I16: RACPad Support | J16: Rashmitha Shetty | K16: RACPAD - Payment | M16: PRB0044395 | O16: 04753 - MARTINSVILLE - A - M0033 - R0007 - S08 - RACUSA | P16: Incident-App-DataFixDeployed | Q16: Incident INCTEC1616522 closed based on closure of change CHG0051338 | R16: SR | S16: Payment | T16: Payment reversal | U16: =VLOOKUP(T16,'Standard Type of Issue'!$B$1:$C$332,2,0) -> Payment reversal
A17: INCTEC1616553 | B17: 46121.459 | C17: 4 - Low | D17: Closed | E17: Phone | F17: FALSE | G17: RACPAD Customer refund issue | H17: Co-worker name: Erik Sadlowski Employee ID: 369514 Store: 00892 Customer name: Terrence Lakin Customer ID: 109571545 Agreement #: 8173477983 Receipt #: 462597851 Amount #: $152.70 Need to refund on this Card: Card ending with 9421 Issue: CW called and mentioned need to refund this Amount #: $152.70 to the customer. Because customer is using 2account and CW charged from the wrong account. So, need to refund back to the customer. But CW is unable to refund back to the customer. Need help with this refund. | I17: RACPad Support | J17: Aditi Nayak | K17: RACPAD - Payment | M17: PRB0044395 | O17: 00892 - FARGO - A - M0529 - R0040 - S07 - RACUSA | P17: Incident-App-DataFixDeployed | Q17: Resolution Steps: Reversed receipt 462507851 for customer Terrence Lakin. Treasury Team has initiated refund of $261.12. | S17: Payment | T17: Payment reversal | U17: =VLOOKUP(T17,'Standard Type of Issue'!$B$1:$C$332,2,0) -> Payment reversal
A18: INCTEC1623469 | B18: 46141.636 | C18: 4 - Low | D18: Acknowledged | E18: Self Service | F18: TRUE | G18: RACPAD - Account Management | Past Due List | | H18: dryers on account wont allow us to drop them off the account Customer ID: 7261744 Customer Name: Danny Collins Date and Time Issue Was Occured: 2026-03-24 15:15:45 | I18: RACPad Support | J18: Prasanth K | K18: RACPAD - Account Management | M18: PRB0044395 | O18: 00381 - COLUMBUS-NORTH - A - M0482 - R0008 - S07 - RACUSA | S18: Payment | T18: Payment reversal | U18: =VLOOKUP(T18,'Standard Type of Issue'!$B$1:$C$332,2,0) -> Payment reversal
A19: INCTEC1616947 | B19: 46122.555 | C19: 4 - Low | D19: Closed | E19: Phone | F19: FALSE | G19: RACFI-Racpad || Reverse Payment | H19: issue : Need to Reverse Payment Customer Name : FILIBERTO LOPEZ Customer ID : 111539786 Amounts need to refund: $759.49 Receipt ID: 459642370 4 Last dight number of CC : 2394 | I19: RACPad Support | J19: Aditi Nayak | K19: RACPAD - Payment | M19: PRB0044395 | O19: 00747 - VISALIA-MOONEY BLVD - A - M0331 - R0999 - S098 - RACFI | P19: Incident-App-DataFixDeployed | Q19: As per the request, we have reversed the following receipt: 459642370 Since this is a Franchise Store, the Treasury team is unable to issue a refund for a payment processed at a franchise location. They do not have access to the chain code under which the transaction was completed. Therefore, informed store to reach out to the Franchise Back Office to issue the refund to the customer | R19: SR | S19: Payment | T19: Payment reversal | U19: =VLOOKUP(T19,'Standard Type of Issue'!$B$1:$C$332,2,0) -> Payment reversal
A20: INCTEC1616953 | B20: 46122.561 | C20: 4 - Low | D20: Closed | E20: Self Service | F20: FALSE | G20: RACPAD - Agreement | Agreement Void | | H20: It is not letting us void a special order from 12/30/23 because it wants us to reverse payment. We cannot reverse payment because we have taken several payments that are to other agreements. We need this agreement void to be able to transfer customer to new store. This store 02174 is closing and it is urgent that we get this done quickly. Agreement Number: 08253475278 Customer ID: 109535772 Customer Name: Wilber I Caxaj Ajanel Date and Time Issue Was Occured: 2026-04-10 13:24:52 | I20: RACPad Support | J20: Vandana K | K20: RACPAD - Agreement | M20: PRB0044395 | O20: 02174 - AUSTIN - RESEARCH - I - M0066 - R0079 - S07 - RACUSA | P20: Incident-App-DataFixDeployed | Q20: Steps taken: As requested, we have voided the agreement 08253475278. Send the confirmation mail and follow-up mail to the store Tried reaching the store via store call,not able to connect Category: Agreement Hence proceeding with closing the ticket expecting that the request is fulfilled,if not please raise a new ticket | S20: Payment | T20: Payment reversal | U20: =VLOOKUP(T20,'Standard Type of Issue'!$B$1:$C$332,2,0) -> Payment reversal
A21: INCTEC1623767 | B21: 46142.544 | C21: 4 - Low | D21: Resolved | E21: Self Service | F21: TRUE | G21: RACPAD - Payment | Customer Refund | | H21: Customer was a level 3 during process of taking payment. Her level changed to a level 5 after payment was taken for the electronic. Level 5 customers are not allowed electronics on rent. I went to process a refund and got the error below . Agreement Number: 8175457661 Customer ID: 8175457661 Customer Name: ADRIANNA BEST Date and Time Issue Was Occured: 2026-04-30 12:59:09 | I21: RACPad Support | J21: Ashwini Shetty | K21: RACPAD - Payment | M21: PRB0044395 | O21: 00391 - WARNER ROBBINS - A - M0482 - R0008 - S07 - RACUSA | P21: Incident-App-TechnicalWorkaround | Q21: Called store to inform that the amount $2.00 is partially reversed to customer account. once a receipt has been partially reversed, the remaining amount cannot be reversed from the backend. For the remaining amount, the store must submit a Check Request through Accounts Payable Also sent email for check request steps. CW agreed Hence proceeding to close the ticket | S21: Payment | T21: Payment reversal | U21: =VLOOKUP(T21,'Standard Type of Issue'!$B$1:$C$332,2,0) -> Payment reversal
A22: INCTEC1617021 | B22: 46122.666 | C22: 4 - Low | D22: Closed | E22: Self Service | F22: FALSE | G22: RACPAD - Payment | Customer Refund | | H22: Customer Name: Daisy Leach Last 4 of Card Used: 5987 Exact Amount of Refund: 52.82 Exact Date of Refund: 4/10/2026 Agreement or Receipt #: 461680155 Detailed Description of Issue: Ordered a fridge and when we got there hotel owner said we were not allowed to deliver said fridge. therefor i want to refund her down payment | I22: RACPad Support | J22: Pratik Singar | K22: RACPAD - Payment | M22: PRB0044395 | O22: 03540 - GREENFIELD-STATE - A - M0177 - R0019 - S08 - RACUSA | P22: Incident-App-DataFixDeployed | Q22: As per request We have reversed the receipt 461680155. Received treasury mail as well. Please refer attachment. | S22: Payment | T22: Payment reversal | U22: =VLOOKUP(T22,'Standard Type of Issue'!$B$1:$C$332,2,0) -> Payment reversal
A23: INCTEC1617058 | B23: 46122.718 | C23: 4 - Low | D23: Closed | E23: Self Service | F23: FALSE | G23: RACPAD - Payment | Customer Refund | | H23: Customer Name: KEVIN BOLTON Last 4 of Card Used: 7016 Exact Amount of Refund: $127.50 Exact Date of Refund: 04/10/2026 Agreement or Receipt #: 462444692 Detailed Description of Issue: On April 8th we started the agreement the customer did a down payment of $127.50. We went and tried to deliver the washer and dryer but it did not fit in the spot that had so they decided they did not want it. We tried to reverse the payment and it showed reversed but it was for $0 but it did change the due date and took it back to April 8th. We tried to reserve it again and the amount for just BP showed up for $14.14 and that reversed like normal. I thought that maybe now if I tried to reserve it again it would have the remaining amount but it says No Eligible Payment Found For This Customer To Reverse. So I am not sure what amount got reversed back to him it should have been the full amount of $127.50 if only the BP did we would still owe him $113.36. Are you able to see if anything reversed back to him? | I23: RACPad Support | J23: Rashmitha Shetty | K23: RACPAD - Payment | M23: PRB0044395 | O23: 01710 - CRYSTAL CITY - A - M0538 - R0039 - S07 - RACUSA | P23: Request-Fulfilled | Q23: The given receipt already reversed we cannot reverse it again from backend and the agreement is already returned to store. so, reached out to store multiple times to get the details on what is the current issue here, but haven't received any response. Thus, resolving the incident. | R23: SR | S23: Payment | T23: Payment reversal | U23: =VLOOKUP(T23,'Standard Type of Issue'!$B$1:$C$332,2,0) -> Payment reversal
A24: INCTEC1623871 | B24: 46142.738 | C24: 4 - Low | D24: Awaiting Confirmation | E24: Self Service | F24: TRUE | G24: RACPAD - Payment | Reverse Payment | | H24: Customer Name: KATREIONA STARKS Customer ID: 111261501 Agreement Number: 8175461284 Date of payment :04/14/2026 Mode of payment : Credit card Last 4 digit :3940 Description: CW is unable to refund the payment $79.91 because it is not a recent transaction need help for same | I24: RACPad Support | J24: Sushmitha Sannidhi | K24: RACPAD - Payment | M24: PRB0044395 | O24: 03742 - EASTEX-LITTLE YORK - A - M0555 - R0079 - S07 - RACUSA | S24: Payment | T24: Payment reversal | U24: =VLOOKUP(T24,'Standard Type of Issue'!$B$1:$C$332,2,0) -> Payment reversal
A25: INCTEC1617222 | B25: 46123.474 | C25: 4 - Low | D25: Closed | E25: Phone | F25: FALSE | G25: Racpad Customer -unable to transfer a customer Store is getting closed | H25: Customer Name: Margarita Ayala Customer ID:6414444 Agreement Number:8172369180/100016533169 Description :unable to transfer a customer Store is getting closed need help with same | I25: RACPad Support | J25: Tejas Acharya | K25: RACPAD - Agreement | M25: PRB0044395 | O25: 02516 - DORCHESTER-COLUMBIA RD - I - M0028 - R0002 - S07 - RACUSA | P25: Incident-App-DataFixDeployed | Q25: Steps taken for resolution: Agreement #07987172389 has been voided as requested. Category: racpad agreement | R25: SR | S25: Payment | T25: Payment reversal | U25: =VLOOKUP(T25,'Standard Type of Issue'!$B$1:$C$332,2,0) -> Payment reversal
A26: INCTEC1617238 | B26: 46123.502 | C26: 4 - Low | D26: Closed | E26: Self Service | F26: FALSE | G26: RACPAD - Payment | Customer Refund | | H26: Customer Name: Tristan Hayden Last 4 of Card Used: 1936 Exact Amount of Refund: $57.87 Exact Date of Refund: 04/11/2026 Agreement or Receipt #: 462749033 Detailed Description of Issue: Customer returned the merchandise prior to due date without the controller. Agreement wasn't taken down immediately upon waiting for the controller. Controller has been returned. Customer requests refund on last payment. | I26: RACPad Support | J26: Aditi Nayak | K26: RACPAD - Payment | M26: PRB0044395 | O26: 03596 - HARTFORD CITY-JEFFERSON - A - M0177 - R0019 - S08 - RACUSA | P26: Incident-App-DataFixDeployed | Q26: Resolution steps: As per the request, we have reversed receipt: 462749033 and the Treasury team has initiated the refund. Category: Receipt reversal | S26: Payment | T26: Payment reversal | U26: =VLOOKUP(T26,'Standard Type of Issue'!$B$1:$C$332,2,0) -> Payment reversal
A27: INCTEC1617765 | B27: 46125.644 | C27: 4 - Low | D27: Closed | E27: Self Service | F27: FALSE | G27: RACPAD - Agreement | Agreement Return | | H27: We cannot void the rental agreement. We are unable to "reopen" the scheduled delivery that was cancelled, therefore it will not allow me to void the agreement. PLEASE DO NOT REFUND THE MOST RECENT RECEIPTS. Agreement Number: 8175006926 Customer ID: 954200 Customer Name: VERONICA D TREJO-GALINO Date and Time Issue Was Occured: 2026-03-30 15:22:18 | I27: RACPad Support | J27: roopesh pothodi | K27: RACPAD - Agreement | M27: PRB0044395 | O27: M0120 - - M0120 - R0020 - S08 - RTO | P27: Incident-App-DataFixDeployed | Q27: Steps taken for resolution: The agreement and inventory tables have been updated to ensure the inventory and agreement statuses are correctly reflected. Category: Void Agreement | S27: Payment | T27: Payment reversal | U27: =VLOOKUP(T27,'Standard Type of Issue'!$B$1:$C$332,2,0) -> Payment reversal
A28: INCTEC1618156 | B28: 46126.611 | C28: 4 - Low | D28: Closed | E28: Self Service | F28: FALSE | G28: RACPAD - Payment | Customer Refund | | H28: Customer Name: MIRIAM KAHAN Last 4 of Card Used: 6004 Exact Amount of Refund: $124.87 Exact Date of Refund: 04/14/26 Agreement or Receipt #: 462310292 Detailed Description of Issue: We picked up the recliner on the same day the autopay pulled. We need to refund the customer please. | I28: RACPad Support | J28: Aditi Nayak | K28: RACPAD - Payment | M28: PRB0044395 | O28: 05046 - - A - M0007 - R0007 - S08 - RACUSA | P28: Request-Fulfilled | Q28: Informed Richard that DM can submit the RACinet form his behalf. If the DM is also unable to submit the form due to access issues, please reach out to AccountsPayable@rentacenter.com for further assistance. | S28: Payment | T28: Payment reversal | U28: =VLOOKUP(T28,'Standard Type of Issue'!$B$1:$C$332,2,0) -> Payment reversal
A29: INCTEC1618176 | B29: 46126.635 | C29: 4 - Low | D29: Closed | E29: Self Service | F29: FALSE | G29: RACPAD - Payment | Customer Refund | | H29: Customer Name: Ramona Smith Last 4 of Card Used: 1187 Exact Amount of Refund: 88.30 Exact Date of Refund: 03/04/2026 Agreement or Receipt #: A#8174968449 Detailed Description of Issue: Refund owed customer as the agreement was canceled (not delivered), and refund was not run before being agreement was closed. | I29: RACPad Support | J29: Rashmitha Shetty | K29: RACPAD - Payment | M29: PRB0044395 | O29: 02447 - CHESAPEAKE - A - M0007 - R0007 - S08 - RACUSA | P29: Incident-App-DataFixDeployed | Q29: As requested we have reversed the receipt and voided the agreement and treasury team has initiated the refund for the same. And informed store to allow up to 7-10 business days for the customer to receive funds back to the card used. Resolving the incident as request is completed. Category: Receipt Reversal and Void agreement | R29: SR | S29: Payment | T29: Payment reversal | U29: =VLOOKUP(T29,'Standard Type of Issue'!$B$1:$C$332,2,0) -> Payment reversal
A30: INCTEC1618214 | B30: 46126.686 | C30: 4 - Low | D30: Closed | E30: Email | F30: FALSE | G30: Transfer Issue 4705-RACPAD | H30: Thanks, Siva Bhargavi RACPad Production Support +1 6605413327 [cid:image001.jpg@01DBA816.356267B0] _____________________________________________ From: Melody Cassel <melody.cassel@upbound.com> Sent: Tuesday, April 14, 2026 4:07 PM To: RACPad Support <RACPadSupport@rentacenter.com> Cc: Joshua Castor <Josh.Castor@rentacenter.com>; Seema Rani <Seema.Rani@Rentacenter.com> Subject: Transfer Issue 4705 Importance: High Hello Team, Can we please investigate two problems. 1st Store 04705 is unable to void agreement 07950910418 as it is requesting a payment reversal that has already been completed. See screenshots below. 2nd issue store 4705 is trying to transfer agreements 8174517850 and 8169769123 to store 3770 but the transfer button is disabled. My assumption is because the agreement above is pending, if this is the case can you please void 07950910418 so the store can proceed with the transfer. Melody Cassel Director of Product Management Melody.Cassel@Upbound.com<mailto:Melody.Cassel@Upbound.com> Upbound Group, Inc. / 5501 Headquarters Dr., Plano, TX 75024 / Ticker: UPBD | I30: RACPad Support | J30: Rashmitha Shetty | K30: RACPAD - Agreement | M30: PRB0044395 | O30: H0003 - - Active - FSC | P30: Incident-App-DataFixDeployed | Q30: As per the request We have voided the agreement#07950910418. Resolving the incident as request is completed. Category: Void Agreement | R30: SR | S30: Payment | T30: Payment reversal | U30: =VLOOKUP(T30,'Standard Type of Issue'!$B$1:$C$332,2,0) -> Payment reversal
A31: INCTEC1618409 | B31: 46127.361 | C31: 4 - Low | D31: Closed | E31: Other | F31: FALSE | G31: Test agreement cancellation | H31: Following test agreement was created in prod as part of predeployment validation. Requesting to cancel this agreement and refund the related payments. Need to be routed to RACPAD support team. First name : testsfcc Last Name: Verifycodefive Agreement # - 8175318830 | I31: RACPad Support | J31: Rashmitha Shetty | K31: RACPAD - Agreement | M31: PRB0044395 | O31: H0003 - - Active - FSC | P31: Incident-App-DataFixDeployed | Q31: Incident INCTEC1618409 closed based on closure of change CHG0051445 | R31: SR | S31: Payment | T31: Payment reversal | U31: =VLOOKUP(T31,'Standard Type of Issue'!$B$1:$C$332,2,0) -> Payment reversal
A32: INCTEC1618736 | B32: 46128.382 | C32: 4 - Low | D32: Closed | E32: Email | F32: FALSE | G32: Special Order PO -Racpad | H32: From: Melissa Swarbrick <Melissa.Swarbrick@racfranchising.com> Sent: Thursday, April 16, 2026 7:35 PM To: RACPad Support <RACPadSupport@rentacenter.com> Cc: Melissa Berry <Melissa.Berry@rentacenter.com> Subject: FW: Special Order PO Hi, can you help the store with this issue? Thank you From: Carlos Rodriguez <Carlos.Rodriguez@rentacenter.com<mailto:Carlos.Rodriguez@rentacenter.com>> Sent: Wednesday, April 15, 2026 10:45 PM To: Melissa Swarbrick <Melissa.Swarbrick@racfranchising.com<mailto:Melissa.Swarbrick@racfranchising.com>>; Melissa Berry <Melissa.Berry@rentacenter.com<mailto:Melissa.Berry@rentacenter.com>> Subject: RE: Special Order PO Melissa, Open a ticket with RACPad Support and send me the ticket number so I can escalate. Thank you, Carlos Rodriguez From: Melissa Swarbrick <Melissa.Swarbrick@racfranchising.com<mailto:Melissa.Swarbrick@racfranchising.com>> Sent: Tuesday, April 14, 2026 2:48 PM To: Melissa Berry <Melissa.Berry@rentacenter.com<mailto:Melissa.Berry@rentacenter.com>> Cc: Carlos Rodriguez <Carlos.Rodriguez@rentacenter.com<mailto:Carlos.Rodriguez@rentacenter.com>> Subject: RE: Special Order PO Hi Carlos, is this something you can help with? From: Melissa Berry <Melissa.Berry@rentacenter.com<mailto:Melissa.Berry@rentacenter.com>> Sent: Tuesday, April 14, 2026 2:42 PM To: Melissa Swarbrick <Melissa.Swarbrick@racfranchising.com<mailto:Melissa.Swarbrick@racfranchising.com>> Subject: Re: Special Order PO That's because all the PO's were canceled already however because the PO is not attached. I can't void the special order to then transfer his other account so I'm not really sure what to do. Get Outlook for iOS<https://aka.ms/o0ukef> ________________________________ From: Melissa Swarbrick <Melissa.Swarbrick@racfranchising.com<mailto:Melissa.Swarbrick@racfranchising.com>> Sent: Tuesday, April 14, 2026 2:34:38 PM To: Melissa Berry <Melissa.Berry@rentacenter.com<mailto:Melissa.Berry@rentacenter.com>> Subject: RE: Special Order PO Hi, I looked up this model and can't find a PO to reinstate for your store? Thanks From: Melissa Berry <Melissa.Berry@rentacenter.com<mailto:Melissa.Berry@rentacenter.com>> Sent: Tuesday, April 14, 2026 12:17 PM To: Melissa Swarbrick <Melissa.Swarbrick@racfranchising.com<mailto:Melissa.Swarbrick@racfranchising.com>> Subject: Re: Special Order PO SO yes, we need to reinstate the PO # so we can take off the customer account, then cancel the PO and transfer the account to another store. I don't have the P.O #; however, I do have RMS-200038135. Will this work? Thanks, Melissa ________________________________ From: Melissa Swarbrick <Melissa.Swarbrick@racfranchising.com<mailto:Melissa.Swarbrick@racfranchising.com>> Sent: Friday, April 10, 2026 12:06 PM To: Melissa Berry <Melissa.Berry@rentacenter.com<mailto:Melissa.Berry@rentacenter.com>> Cc: Store 04832 <Store.04832@rentacenter.com<mailto:Store.04832@rentacenter.com>>; Store 01176 <Store.01176@rentacenter.com<mailto:Store.01176@rentacenter.com>> Subject: RE: Special Order PO Hi, are you needing the PO reinstated? What is the PO number? Thanks From: Melissa Berry <Melissa.Berry@rentacenter.com<mailto:Melissa.Berry@rentacenter.com>> Sent: Friday, April 10, 2026 10:39 AM To: Melissa Swarbrick <Melissa.Swarbrick@racfranchising.com<mailto:Melissa.Swarbrick@racfranchising.com>> Cc: Store 04832 <Store.04832@rentacenter.com<mailto:Store.04832@rentacenter.com>>; Store 01176 <Store.01176@rentacenter.com<mailto:Store.01176@rentacenter.com>> Subject: Special Order PO Melissa anyway you can assist me with this. This customer did a special order and because PO's got canceled I can't check it in or void the sale and can transfer the account out of the closing store. If this is not something you can help with, can you please let me know how can? See pic below Thanks Melissa Berry D0156 [cid:image001.png@01DCCD29.81051760] | I32: RACPad Support | J32: Tejas Acharya | K32: RACPAD - Agreement | M32: PRB0044395 | O32: 04832 - BONITA BEACH ROAD - I - M0156 - R0024 - S08 - RACUSA | P32: Incident-App-DataFixDeployed | Q32: Steps taken for resolution: Voided the agreement and transferred the customer account to store 4143. Category: Racpad Agreement | S32: Payment | T32: Payment reversal | U32: =VLOOKUP(T32,'Standard Type of Issue'!$B$1:$C$332,2,0) -> Payment reversal
A33: INCTEC1618817 | B33: 46128.452 | C33: 4 - Low | D33: Closed | E33: Self Service | F33: FALSE | G33: RACPAD - Agreement | Agreement Void | | H33: This store is closing down and this customer had something on customer order waiting to come and I need to void it to transfer the customer to another store. The system wont let me void it because it wants me to reverse the payment for it. I can't reverse the payment because it wasn't the last transaction on the account. Agreement Number: 8175159437 Customer ID: 17012876 Customer Name: Linda Clark Date and Time Issue Was Occured: 2026-04-16 10:49:42 | I33: RACPad Support | J33: Rashmitha Shetty | K33: RACPAD - Agreement | M33: PRB0044395 | O33: 32009 - - I - M0136 - R0008 - S07 - RACUSA | P33: Incident-App-DataFixDeployed | Q33: As requested, we have voided the agreement#8175159437. Resolving this incident after getting store confirmation. | S33: Payment | T33: Payment reversal | U33: =VLOOKUP(T33,'Standard Type of Issue'!$B$1:$C$332,2,0) -> Payment reversal
A34: INCTEC1618928 | B34: 46128.549 | C34: 4 - Low | D34: Closed | E34: Phone | F34: FALSE | G34: Racpad issue | H34: Emp name: Dalton Craig Emp id: 321288 Store number: 02141 Customer name: Desiree Cahill Wood Customer id: 109984058 Agreement number: 8175346285 Item number: 9999221150439 Reason for : User need to exchange the refrigerator in Rac exchange program. So user is trying to void the agreement but he is getting error while trying to do so Error snap is attached | I34: RACPad Support | J34: ankita singh | K34: RACPAD - Agreement | M34: PRB0044395 | O34: 02141 - KNOXVILLE-ASHVILLE - A - M0202 - R0070 - S08 - RACUSA | P34: Incident-NoIssueFound | Q34: Called the store and spoke with Dalton, Confirmation has been received that the agreement has been delivered and the RAC exchange has been completed. As the issue is resolved, we are proceeding with closing the ticket. | S34: Payment | T34: Payment reversal | U34: =VLOOKUP(T34,'Standard Type of Issue'!$B$1:$C$332,2,0) -> Payment reversal
A35: INCTEC1619048 | B35: 46128.695 | C35: 4 - Low | D35: Closed | E35: Phone | F35: FALSE | G35: RACFI-RacPad Agreement Issue | H35: Cust Name & ID : Bernard Castillo - 115077885 Agreement # : 8175070866 User told that he is unable to void the above mentioned agreement | I35: RACPad Support | J35: Lalit RameshTurkar | K35: RACPAD - Agreement | M35: PRB0044395 | O35: 02635 - LYNNWOOD-LONG BEACH BLVD - A - M0993 - R0999 - S098 - RACFI | P35: Incident-App-DataFixDeployed | Q35: Hi Store , as per the request we have made the changes and Agreement has been voided. Attached screenshot for your reference. | S35: Payment | T35: Payment reversal | U35: =VLOOKUP(T35,'Standard Type of Issue'!$B$1:$C$332,2,0) -> Payment reversal
A36: INCTEC1619665 | B36: 46130.408 | C36: 4 - Low | D36: Closed | E36: Self Service | F36: FALSE | G36: RACPAD - Payment | Customer Refund | | H36: Customer Name: ISABEL FLORES Last 4 of Card Used: 8604 Exact Amount of Refund: 10.00 Exact Date of Refund: N/A Agreement or Receipt #: 8175306780 RECEIPT- 462653896 Detailed Description of Issue: I NEED TO REFUND THE 10 DOLLAR RECEIPT SO I CAN VOID THE AGREEMENT | I36: RACPad Support | J36: Sushmitha Sannidhi | K36: RACPAD - Payment | M36: PRB0044395 | O36: 00794 - LAS VEGAS-DECATUR BLVD - A - M0257 - R0050 - S07 - RACUSA | P36: Incident-App-DataFixDeployed | Q36: Receipt #462653896 is reversed from backend as per the request. For the reversed receipt, refund request is raised by treasury team for the overpayment collected in the amount of $10 as requested. Please allow up to 7-10 business days for the customer to receive funds back to the card . Reversed Receipt number: 462653896 | S36: Payment | T36: Payment reversal | U36: =VLOOKUP(T36,'Standard Type of Issue'!$B$1:$C$332,2,0) -> Payment reversal
A37: INCTEC1619680 | B37: 46130.434 | C37: 4 - Low | D37: Closed | E37: Phone | F37: FALSE | G37: Customer suspense account | H37: Customer name: Vicky Stewart Customer ID: 6176391 Agreement: 8174616144 For this agreement dashboard shows that she has money on suspense account $(202.65) When store try to collect that it says transaction failed Expectation: Store need to collect payment from customer but dashboard says store owe $(202.65) in suspense account and store not able to collect that from customer Please do the needful | I37: RACPad Support | J37: monisha d | K37: RACPAD - Payment | M37: PRB0044395 | O37: 04415 - AHOSKIE-MEMORIAL - A - M0386 - R0007 - S08 - RACUSA | P37: Incident-App-DataFixDeployed | Q37: As per the request, receipt 463613607 has been reversed successfully. We had sent two follow‑up emails requesting confirmation; however, no response was received. hence, we are resolving this incident. Incident INCTEC1619680 closed based on closure of change CHG0051456. | S37: Payment | T37: Payment reversal | U37: =VLOOKUP(T37,'Standard Type of Issue'!$B$1:$C$332,2,0) -> Payment reversal
A38: INCTEC1619718 | B38: 46130.503 | C38: 4 - Low | D38: Closed | E38: Phone | F38: FALSE | G38: RACPAD - Need to void agreement | H38: Store number: 01107 Coworker name and ID: Joanna Ortiz (348971) Customer name and number: Isaiah Padilla (114921646) Issue description: Coworker requested to void the agreement and move the item to the inventory. Agreement # 8175352363 Item # 9999222251029 Steps taken to arrive at problem: Time of occurrence (Recreate the issue and notate the time if needed): Screen shot required: YES | I38: RACPad Support | J38: Tejas Acharya | K38: RACPAD - Agreement | M38: PRB0044395 | O38: 01107 - DENVER-COLFAX & C NORTH - A - M0235 - R0011 - S07 - RACUSA | P38: Incident-App-DataFixDeployed | Q38: Steps taken for resolution: Agreement #8175352363. has been voided as requested. Category: Racpad Agreement | R38: SR | S38: Payment | T38: Payment reversal | U38: =VLOOKUP(T38,'Standard Type of Issue'!$B$1:$C$332,2,0) -> Payment reversal
A39: INCTEC1620261 | B39: 46132.536 | C39: 4 - Low | D39: Closed | E39: Self Service | F39: FALSE | G39: RACPAD - Payment | Customer Refund | | H39: Customer placed order on line for item out of approval limit. Order was cancelled from Ashley on 4-16-26 PO#16421674. Refund amount of $44.16 Agreement Number: 8175349194 Customer ID: 108195697 Customer Name: Anthony Brookshire Date and Time Issue Was Occured: 2026-04-20 03:01:02 | I39: RACPad Support | J39: Aditi Nayak | K39: RACPAD - Payment | M39: PRB0044395 | O39: 04064 - BELLEVUE PARK PLAZA - A - M0538 - R0039 - S07 - RACUSA | P39: Incident-App-DataFixDeployed | Q39: Upon checking, we could see the amount $-3.00 partially refunded to the customer. once a receipt has been partially reversed, the remaining amount cannot be reversed from the backend. For the remaining amount, the store must submit a Check Request through Accounts Payable. | S39: Payment | T39: Payment reversal | U39: =VLOOKUP(T39,'Standard Type of Issue'!$B$1:$C$332,2,0) -> Payment reversal
A40: INCTEC1620292 | B40: 46132.575 | C40: 4 - Low | D40: Closed | E40: Self Service | F40: FALSE | G40: RACPAD - Payment | Customer Refund | | H40: Customer Name: Becca Gahm Last 4 of Card Used: 1937 Exact Amount of Refund: 773.53 Exact Date of Refund: ASAP Agreement or Receipt #: 8173618046 & 100015861454 Detailed Description of Issue: Customer ordered a refrigerator in October, it arrived and was set for delivery, but the customer never received it and had cancelled the order, but it wasn't communicated to the store. She had autopay set up from the start, and it was pulling every two weeks since December. I have attached her payment history as well as her initial payment for the order (it doesn't show on the payment history). The total amount comes to $773.53. While we were not able to get a hold of her until now (she was supposed to move here from Colorado, but that changed at the end of last year), I do feel that she is entitled to her money. The delivery was never confirmed in the system, either. | I40: RACPad Support | J40: Aditi Nayak | K40: RACPAD - Payment | M40: PRB0044395 | O40: 04059 - SPRINGFIELD-N. KANSAS - A - M0214 - R0080 - S08 - RACUSA | P40: Incident-App-DataFixDeployed | Q40: Closing the ticket as per store confirmation | S40: Payment | T40: Payment reversal | U40: =VLOOKUP(T40,'Standard Type of Issue'!$B$1:$C$332,2,0) -> Payment reversal
...

Sheet Updated Issue wise details_Std
A3: Row Labels | B3: Count of Number
A4: BigPanda | B4: 483
A5: Others - Misc | B5: 141
A6: Customer Login Issue (EXT) | B6: 100 | E6: Amith - Roopesh
A7: Store Access | B7: 97 | D7: 1: Access request - how many SR are created for access 2: Can it be shift left or automated 3: Categories in access request | E7: Nagaraj
A8: Payment reversal | B8: 66 | D8: Categories in Payment reversal | E8: Proc is having issue, due to which automation is on hold | F8: QA Team
A9: Payment Query | B9: 60 | D9: Categories in Payment query | E9: Nikhil/Ashwin
A10: AutoPay | B10: 51 | D10: Will be discussed tomorrow Trailblazer call | E10: Prashanth
A11: Switch Out Issue | B11: 49 | D11: NA
A12: Unable to confirm delivery | B12: 49 | D12: Discussed in Trailblazer call - followup to be done with Seema | E12: Fixed
A13: Payment Error | B13: 38 | D13: NA
A14: Daily task | B14: 38 | D14: Inventory rental Stats overshot cash/non-cash Bad display | E14: If these are SOP based, can we look for automating them
A15: Monitoring | B15: 36 | D15: Threshold revisit and change the monitoring process for INC creation
A16: Cancel the Manual PO | B16: 36 | D16: Automation done through self service portal | E16: Nagaraj
A17: Cancel the RMS PO | B17: 32 | D17: Data fix done for Old RMS POs
A18: Unable to receive the Purchase order | B18: 30 | D18: Single scenario with workaround - done through data fix for now | E18: Nagaraj
A19: Customer Issue | B19: 29 | D19: For any pattern, can we look to create a SOP | E19: Prashanth
A20: 2 way sync | B20: 26 | D20: RCA is progress - will be taken up for automation | E20: Nagaraj
A21: Agreement Issue | B21: 24 | D21: NA
A22: Inventory Issue | B22: 23 | D22: NA
A23: Agreement Void Issue | B23: 20 | D23: NA
A24: DQ-Agreement | B24: 20 | D24: sync DQ automation is already in Place which executed on daily basis | E24: Nagaraj
A25: Account Report Request | B25: 18 | D25: Mostly email request, so team can create SR instead of INC. another option to automate end to end using Business user form | E25: Muneer
A26: Training Issue | B26: 17 | D26: PRB Resolved
A27: Inventory Status Issue | B27: 16
A28: Report discrepency | B28: 15
A29: Agreement Creation Issue | B29: 15
A30: Duplicate ticket | B30: 14
A31: PIN reset | B31: 14 | D31: Enhancement - Already discussed with Seema and dropped email
A32: DQ-Inventory | B32: 9
A33: One Time Issue | B33: 9
A34: Agreement Status | B34: 8
A35: Drop reconciliation | B35: 8
A36: Agreement Transfer Issue | B36: 7
A37: Query | B37: 7
A38: Pricing request | B38: 7
A39: Payment issue | B39: 7
A40: Pricing Issue | B40: 7
A41: Chargeback | B41: 6
A42: Duplicate customers record | B42: 6
...

Sheet Issue wise details_old
A1: Team | B1: Type Of Issue | C1: No of Incidents reported | D1: Problem | E1: Remarks | F1: Module
A2: App Support | B2: BigPanda | C2: 483
A3: App Support/DS | B3: Unable to link the agreement(Due to login issue -most are EXT tickets) | C3: 94 | D3: PRB0044676
A4: App Support | B4: Access | C4: 75 | D4: PRB0045218 | F4: Access
A5: App Support | B5: Payment reversal | C5: 58 | D5: PRB0044395 | F5: Payment
A6: App Support | B6: AutoPay | C6: 51 | D6: PRB0046103
A7: App Support | B7: Unable to confirm delivery | C7: 49 | D7: PRB0044979 | F7: Delivery
A8: App Support | B8: Payment not reflecting in RACPAD | C8: 45 | F8: Payment
A9: App Support | B9: Agreement switch-out completed, but inventory remains in "Pending Switch Out" status | C9: 44 | D9: PRB0045906 | F9: Inventory
A10: Data Services | B10: Monitoring | C10: 36
A11: App Support | B11: Cancel the Manual PO | C11: 34 | D11: PRB0045846 | F11: PO Related
A12: App Support | B12: Cancel the RMS PO | C12: 32 | D12: PRB0045373 | F12: PO Related
A13: App Support | B13: Unable to receive the Purchase order | C13: 30 | D13: PRB0046203
A14: Data Services | B14: Daily Task | C14: 29
A15: Data Services | B15: Active Agreement Mismatch | C15: 20
A16: App Support | B16: User having access to old stores in RACPAD | C16: 19 | D16: PRB0046072 | F16: Access
A17: App Support | B17: Amount Mismatch Error on Initial Payment for Customer Order Agreement | C17: 18 | D17: PRB0045088 | F17: Payment
A18: Data Services | B18: 2 way sync | C18: 18
A19: App Support | B19: Level 1 loyalty customer unable to add phone | C19: 17 | D19: PRB0046289 | F19: Add Phone
A20: App Support | B20: Report discrepency | C20: 15 | D20: PRB0044727 | F20: Report
A21: App Support | B21: Duplicate ticket | C21: 14
A22: App Support | B22: PIN Reset | C22: 14 | E22: 5/13: Enhancment request sent - Seema/Divya
A23: App Support | B23: The CW is unable to void the agreements because the Customer Order feature is currently disabled for eclipse RTO Stores. | C23: 12 | D23: PRB0046139
A24: App Support | B24: Generating detailed account report on rental agreements | C24: 11 | D24: PRB0045462 | F24: Report
A25: App Support | B25: Unable to create an agreement | C25: 11 | E25: No issues observed for all the logged incidents
A26: Data Services | B26: Active Inventory Mismatch | C26: 9 | F26: Inventory
A27: App Support | B27: The overridden other charge in the initial payment section is automatically reapplied after completing the agreement | C27: 8 | D27: PRB0046248 | F27: Payment
A28: Data Services | B28: CREATE-INVENTORY-ACTIVITY-LOG | C28: 8 | F28: Inventory
A29: App Support | B29: Unable to proceed with payment | C29: 7 | E29: No issues observed for all the logged incidents | F29: Payment
A30: App Support | B30: Unable to submit Inventory | C30: 7 | E30: No issues observed for all the logged incidents | F30: Inventory
A31: Data Services | B31: Overshort Cash | C31: 7
A32: App Support | B32: Rate Retention for agreements is happening incorrectly. | C32: 6 | D32: PRB0045802
A33: App Support | B33: Duplicate customers record | C33: 6 | D33: PRB0046275
A34: Data Services | B34: Inventory Mismatch | C34: 6 | F34: Inventory
A35: Data Services | B35: Account Report | C35: 6 | F35: Report
A36: App Support | B36: Unable to transfer the agreement | C36: 5 | D36: PRB0045498
A37: App Support | B37: The EPO amount is incorrectly calculated as 0 after the SAC period ends. | C37: 5 | D37: PRB0046266 | F37: PO Related
A38: App Support | B38: Customer charged multiple time | C38: 5
A39: App Support | B39: Customer has not received refund | C39: 5 | F39: Refund
A40: App Support | B40: Unable to void the agreement | C40: 5
...

Sheet Standard Type of Issue
B1: Type Of Issue | C1: Std Type of Issue
A2: 1 | B2: BigPanda | C2: BigPanda
A3: 2 | B3: Unable to link the agreement | C3: Customer Login Issue (EXT)
B4: Login issue | C4: Customer Login Issue (EXT)
A5: 3 | B5: Access | C5: Store Access
A6: 4 | B6: Payment reversal | C6: Payment reversal
A7: 5 | B7: AutoPay | C7: AutoPay
B8: Autopay | C8: AutoPay
A9: 6 | B9: Unable to confirm delivery | C9: Unable to confirm delivery
A10: 7 | B10: Payment not reflecting in RACPAD | C10: Payment Query
A11: 8 | B11: Agreement switch-out completed, but inventory remains in "Pending Switch Out" status | C11: Switch Out Issue
A12: 9 | B12: Monitoring | C12: Monitoring
A13: 10 | B13: Cancel the Manual PO | C13: Cancel the Manual PO
A14: 11 | B14: Cancel the RMS PO | C14: Cancel the RMS PO
A15: 12 | B15: Unable to receive the Purchase order | C15: Unable to receive the Purchase order
A16: 13 | B16: Daily Task | C16: Daily task
A17: 14 | B17: Active Agreement Mismatch | C17: DQ-Agreement
A18: 15 | B18: User having access to old stores in RACPAD | C18: Store Access
A19: 16 | B19: Amount Mismatch Error on Initial Payment for Customer Order Agreement | C19: Payment Error
A20: 17 | B20: 2 way sync | C20: 2 way sync
... A23: 20 | B23: Duplicate ticket | C23: Duplicate ticket
A24: 21 | B24: PIN Reset | C24: PIN reset | D24: PRB WIP
A25: 22 | B25: The CW is unable to void the agreements because the Customer Order feature is currently disabled for eclipse RTO Stores. | C25: Agreement Void Issue
A26: 23 | B26: Generating detailed account report on rental agreements | C26: Account Report Request | D26: Crystal
A27: 24 | B27: Unable to create an agreement | C27: Agreement Creation Issue
A28: 25 | B28: Active Inventory Mismatch | C28: DQ-Inventory
A29: 26 | B29: The overridden other charge in the initial payment section is automatically reapplied after completing the agreement | C29: Payment Error
A30: 27 | B30: CREATE-INVENTORY-ACTIVITY-LOG | C30: 2 way sync
A31: 28 | B31: Unable to proceed with payment | C31: Payment Error
A32: 29 | B32: Unable to submit Inventory | C32: One Time Issue
A33: 30 | B33: Overshort Cash | C33: Daily task
A34: 31 | B34: Rate Retention for agreements is happening incorrectly. | C34: Agreement Issue
A35: 32 | B35: Duplicate customers record | C35: Duplicate customers record
A36: 33 | B36: Inventory Mismatch | C36: Inventory Mismatch
A37: 34 | B37: Account Report | C37: Account Report Request
A38: 35 | B38: Unable to transfer the agreement | C38: Agreement Transfer Issue
... A61: 58 | B61: Agreement price shows more | C61: Agreement Issue
A62: 59 | B62: Error in RmsReserveOrderService
A63: 60 | B63: Update the rate and term request
A64: 61 | B64: Increase in payment amount | C64: Payment Query
...
