Workbook

Sheet Dump
A1: Number | B1: Created | C1: Priority | D1: Status | E1: Short Description | F1: Description | G1: Assignment Group | H1: Assigned to | I1: Action | J1: Parent | K1: Problem | L1: Caused by Change | M1: Module | N1: Type of Issue | O1: One time /Reccuring/Not an issue | R1: 1139
A2: INCTEC1591872 | B2: 46054.027 | C2: 3 - Moderate | D2: Closed | E2: BigPanda Incident: cloud2gcdb - Ok | F2: Incident Summary: -------------------------------------------------------- AI-Generated Incident Analysis Resolved: cloud2gcdb Lambda POST-PAYMENT Event Processing Errors Cleared in prod2 On Feb 1, 2026, at 06:34:16 UTC, 8 'Ok' alerts for 'cloud2gcdb' in 'prod2' (stores 08528, 08614, 08724, 08510, 08610) reported resolved errors in the Lambda 'Cloud2GcdbSubscriptionFilter' during POST-PAYMENT event processing. No current impact; all issues have cleared. At 06:34:16 UTC on Feb 1, 2026, 8 'Ok' alerts were generated for 'cloud2gcdb' in 'prod2', referencing errors in the Lambda 'Cloud2GcdbSubscriptionFilter' while processing POST-PAYMENT events for various stores. The simultaneous 'Ok' status indicates prior errors have been resolved, with no ongoing impact. AWS Lambda functions, such as 'Cloud2GcdbSubscriptionFilter', process events (here, POST-PAYMENT) and can log errors if processing fails. CloudWatch Logs (CWL) and custom log aggregators like Logz.io generate alerts when error patterns are detected. The 'Ok' status means the error condition has cleared—likely after transient issues (e.g., data, connectivity, or downstream service hiccups) were resolved. The identical timestamps suggest a batch resolution or system recovery, not ongoing or sequential failures. The absence of critical/warning alerts and the 'Ok' incident status confirm the system is healthy. No service desk tickets or historical actions suggest no user impact or escalation. | G2: RACPad Support | H2: dazel dsouza | M2: BigPanda | N2: BigPanda | R2: 336
A3: INCTEC1591879 | B3: 46054.106 | C3: 3 - Moderate | D3: Closed | E3: BigPanda Incident: sfcc - Ok (Flapping) | F3: Incident Summary: -------------------------------------------------------- AI-Generated Incident Analysis Critical Data Integrity Failure Impacting Inventory Event Processing in prod2 Lambdas On Sunday, Feb 1, 2026, at 08:27:12 UTC, two warning alerts from 'sfcc-store-inventory-delta-events' Lambda in 'prod2' reported 500 errors due to missing inventory data. At 08:29:14 UTC, a critical alert from 'tcpaeventsubscribe' Lambda indicated a related server error. Three alerts (1 critical, 2 warning) highlight a production-impacting data integrity issue affecting inventory event processing. At 08:27:12 UTC, two warning alerts from 'sfcc-store-inventory-delta-events' Lambda reported 500 errors due to missing 'Inventory' and 'InventoryPrice' data. At 08:29:14 UTC, a critical alert from 'tcpaeventsubscribe' Lambda reported a 500 error in 'ProcessTcpaEventsEntdbService'. The sequence suggests that missing or malformed inventory data in upstream events led to failures in both services, with the issue escalating to a critical state in the downstream 'tcpaeventsubscribe' Lambda. AWS Lambda failures and cascading errors were caused by malformed or incomplete inventory event data, highlighting how upstream data issues can propagate and disrupt downstream services in event-driven architectures. | G3: RACPad Support | H3: dazel dsouza | M3: BigPanda | N3: BigPanda | R3: =R1-R2 -> 803
A4: INCTEC1591881 | B4: 46054.119 | C4: 3 - Moderate | D4: Closed | E4: BigPanda Incident: sfcc - Ok | F4: Incident Summary: -------------------------------------------------------- AI-Generated Incident Analysis Warning: Application Errors in prod2-sfcc-store-inventory-delta-events Lambda Due to Missing Inventory Data (Flapping) On Feb 1, 2026, at 08:27 UTC, two Warning alerts for 'prod2-sfcc-store-inventory-delta-events-lambda-PublishStoreInventoryUpdatestoSFCCSubscriptionFilter' in prod2 signaled repeated 500 errors due to missing Inventory and InventoryPrice fields. The incident is flapping, with 2 warnings and 1 ok alert, affecting the sfcc-store-inventory-delta-events application. At 08:27:12 UTC on Feb 1, 2026, two Warning alerts were triggered for 'prod2-sfcc-store-inventory-delta-events-lambda-PublishStoreInventoryUpdatestoSFCCSubscriptionFilter' in prod2, both with statusCode 500 and error: 'Inventory and InventoryPrice is required'. This indicates the root cause is missing required fields in event payloads for this Lambda function. The Ok alert at 08:29:14 UTC is for a different application and is not causal. AWS Lambda functions process events and require specific payload fields to execute business logic. The error 'Inventory and InventoryPrice is required' with statusCode 500 means the Lambda could not process events due to missing data, resulting in application-level failures. HTTP 500 errors indicate server-side issues, not client or network faults. The simultaneous occurrence of two identical warnings for the same Lambda and error message at 08:27:12 UTC confirms a systemic issue with event payloads, not a transient or isolated error. The incident is flapping, suggesting intermittent resolution or repeated failures, possibly as upstream systems intermittently provide or omit required fields. The Ok alert at 08:29:14 UTC is for a different Lambda and application, with a different error, and does not contribute to the root cause. No user tickets or historical actions are present, so the analysis relies solely on alert evidence. | G4: RACPad Support | H4: dazel dsouza | M4: BigPanda | N4: BigPanda
A5: INCTEC1591882 | B5: 46054.123 | C5: 3 - Moderate | D5: Closed | E5: BigPanda Incident: customer - Warning | F5: Incident Summary: -------------------------------------------------------- | G5: RACPad Support | M5: BigPanda | N5: BigPanda
A6: INCTEC1591883 | B6: 46054.124 | C6: 3 - Moderate | D6: Closed | E6: BigPanda Incident: customer - Ok | F6: Incident Summary: -------------------------------------------------------- AI-Generated Incident Analysis Warning: 'customer' Application Database Update Error (Unique Constraint Violation) in prod2 AWS On Sunday, Feb 1, 2026, at 12:37:09 AM UTC, a warning alert was generated for the 'customer' application in the 'prod2' AWS environment. The incident involves a failed database update due to a unique constraint violation in the 'racadm.phone' table, affecting customer record processing. Only one warning alert was observed. At 12:37:09 AM UTC on Feb 1, 2026, the 'customer' application in the 'prod2' AWS environment triggered a warning due to a failed database update. The root cause is a unique constraint violation (PostgreSQL error 23505) on the 'racadm.phone' table, indicating an attempt to insert or update a record with a key that already exists. PostgreSQL enforces unique constraints to prevent duplicate records based on specified key columns. Error code 23505 occurs when an INSERT or UPDATE operation violates this rule. In this incident, the application attempted to update the 'racadm.phone' table with a key (customer_id, phone_type_id, phone_number, active, primary_flag) that already exists, resulting in a failed operation. This typically points to either a logic flaw in the application (e.g., not checking for existing records before updating) or a data integrity issue. The alert's stack trace and error code confirm the database rejected the operation, and the timing shows this was a single, isolated event. No evidence suggests a monitoring or infrastructure issue; the problem is rooted in application/database interaction. | G6: RACPad Support | M6: BigPanda | N6: BigPanda
A7: INCTEC1591888 | B7: 46054.171 | C7: 4 - Low | D7: Closed | E7: BigPanda Incident: managestoreconfigdbevents - Critical | F7: Incident Summary: -------------------------------------------------------- AI-Generated Incident Analysis Warning: sfcc-store-delta-events Lambda Failing on Invalid Event Objects in Production (prod2) From 02:06:14 to 02:56:15 UTC on Jan 29, 2026, 110 warning alerts were triggered for 'sfcc-store-delta-events' in prod2. The Lambda 'PublishStoreUpdatestoSFCCSubscriptionFilter' failed repeatedly with 500 errors due to invalid event objects (missing 'storeNumber'), impacting backend event processing in Production. Between 02:06:14 and 02:56:15 UTC on January 29, 2026, 110 warning alerts were generated for the Lambda 'prod2-sfcc-store-delta-events-lambda-PublishStoreUpdatestoSFCCSubscriptionFilter'. Each alert shows a 500 error due to 'Invalid Event Object' with 'storeNumber' as 'undefined', indicating repeated ingestion of malformed or incomplete event data. AWS Lambda functions process event-driven data, often triggered by upstream services or event buses. A 500 error with 'Invalid Event Object' and 'storeNumber: undefined' means the function received events missing required fields. This points to either an upstream system emitting malformed events or a misconfiguration in event schema validation. The regular, persistent timing (every 5-6 minutes) and identical error context across all alerts confirm a systemic data quality or integration issue, not a transient or infrastructure problem. The absence of critical alerts and the uniformity of the error further support that the Lambda is functioning but unable to process invalid input, not failing due to resource or runtime errors. No user tickets or historical actions suggest this is a backend integration/data pipeline issue, not a user-facing outage. | G7: RACPad Support | H7: Sreenu Yeturi | I7: RACPAD - Store | M7: BigPanda | N7: BigPanda
A8: INCTEC1591937 | B8: 46054.445 | C8: 3 - Moderate | D8: Closed | E8: BigPanda Incident: cloud2gcdb - Ok | F8: Incident Summary: -------------------------------------------------------- AI-Generated Incident Analysis Resolved: Transient Event Processing Errors in prod2-cloud2gcdb Lambda (Production) On Feb 1, 2026, between 16:36 and 16:57 UTC, 20 resolved alerts indicated transient errors in the 'cloud2gcdb' Lambda (prod2). All alerts are Ok, with no ongoing impact. Affected system: prod2-cloud2gcdb-lambda-Cloud2GcdbSubscriptionFilter in Production. No user tickets or persistent issues detected. Between 16:36:14 and 16:57:09 UTC on Feb 1, 2026, 20 alerts reported errors in processing POST-PAYMENT and one UPDATE-AGREEMENT event in the 'cloud2gcdb' Lambda function in prod2. All alerts are now Ok, indicating the errors were transient and have self-resolved. No ongoing issues are present. AWS Lambda functions (here, 'prod2-cloud2gcdb-lambda-Cloud2GcdbSubscriptionFilter') process events asynchronously. Errors in event processing (e.g., POST-PAYMENT) can trigger alerts if exceptions occur. The clustered alert times suggest a brief spike in errors, possibly due to a transient upstream data or service issue. Since all alerts are Ok, the Lambda resumed normal operation, likely after automatic retries or resolution of the upstream problem. No evidence of persistent faults, infrastructure issues, or user impact is present. The absence of flapping and the Ok status confirm system stability. | G8: RACPad Support | H8: dazel dsouza | M8: BigPanda | N8: BigPanda
A9: INCTEC1591940 | B9: 46054.452 | C9: 3 - Moderate | D9: Closed | E9: BigPanda Incident: processpayment - Ok | F9: Incident Summary: -------------------------------------------------------- AI-Generated Incident Analysis Resolved: processpayment Lambda (prod2/AWS) - Previous Cash App Service 500 Errors On Feb 1, 2026, at 16:45:09 UTC, six Ok alerts signaled recovery for the prod2-processpayment-lambda-ChargePaymentSubscriptionFilter in AWS (prod2). The incident involved prior Cash App Service 500 errors (PAYMENT_FAILURE) in the processpayment application. All systems are now operational; no user impact remains. At 16:45:09 UTC on Feb 1, 2026, six Ok alerts were generated for the prod2-processpayment-lambda-ChargePaymentSubscriptionFilter in AWS. These alerts indicate recovery from prior Cash App Service 500 Internal Server Errors (PAYMENT_FAILURE). The root cause was a transient error in the processpayment lambda, now resolved. HTTP 500 errors in serverless payment processing (AWS Lambda) typically signal unhandled exceptions or downstream service failures. The processpayment lambda likely encountered a temporary issue with the Cash App Service, resulting in PAYMENT_FAILURE. Monitoring systems (logzio_custom) detected the error and, upon resolution, generated Ok alerts. The simultaneous Ok status across all alerts at the same timestamp confirms the service has recovered. No new errors or warnings are present, and the incident status is Ok, indicating no ongoing impact. The absence of flapping and tickets further supports that the issue was transient and is now resolved. | G9: RACPad Support | H9: dazel dsouza | M9: BigPanda | N9: BigPanda
A10: INCTEC1591952 | B10: 46054.489 | C10: 3 - Moderate | D10: Closed | E10: BigPanda Incident: cloud2gcdb - Ok | F10: Incident Summary: -------------------------------------------------------- AI-Generated Incident Analysis Resolved: cloud2gcdb Lambda Event Processing Errors in prod2 Across Multiple Stores On Feb 1, 2026, from 16:36 to 17:38 UTC, 30 Ok-status alerts indicated previously resolved errors in the 'cloud2gcdb' Lambda function (prod2) affecting multiple FIELD SYSTEMS stores. No current impact remains; all systems are operational. No user tickets or ongoing issues were detected. Between 16:36:14 and 17:38:14 UTC on Feb 1, 2026, 30 alerts reported errors processing 'POST-PAYMENT' and one 'UPDATE-AGREEMENT' event in the 'cloud2gcdb' Lambda function across multiple stores in 'prod2'. All alerts are now Ok, indicating the underlying issue was transient and has been resolved. The alerts originated from AWS Lambda (as inferred from 'prod2-cloud2gcdb-lambda-Cloud2GcdbSubscriptionFilter') processing events via CloudWatch Logs. Errors in event processing (e.g., POST-PAYMENT) can result from transient issues such as downstream service unavailability, malformed payloads, or temporary resource constraints. The clustering of alerts at three distinct times suggests batch processing or retries. Since all alerts are now Ok, the Lambda function has resumed normal operation, indicating the root cause was likely a temporary external dependency or data issue, not a persistent code or infrastructure fault. No evidence of systemic or ongoing failure is present. | G10: RACPad Support | H10: Vandana K | M10: BigPanda | N10: BigPanda
A11: INCTEC1591957 | B11: 46054.518 | C11: 3 - Moderate | D11: Closed | E11: BigPanda Incident: processpayment - Ok | F11: Incident Summary: -------------------------------------------------------- AI-Generated Incident Analysis Resolved Transient 500 Errors in processpayment, customer, and deliveryreceipt Applications (prod2/AWS) On Feb 1, 2026, nine Ok-status alerts were generated for processpayment, customer, and deliveryreceipt apps in prod2 (AWS). Earlier, these services experienced transient 500 errors (payment, data, SQL issues), but all were resolved before alerting. No ongoing impact, no user tickets, and all systems are currently healthy. Between 16:45:09Z and 18:20:13Z on Feb 1, 2026, multiple applications in prod2 (AWS) experienced transient 500 errors: processpayment (Cash App Service internal errors), customer (duplicate Okta ID), and deliveryreceipt (UploadReceiptsService SQL error). All issues resolved before alerting, as indicated by Ok status at alert times. HTTP 500 errors indicate server-side failures. For processpayment, the error 'PP_CASHAPP_500' suggests a downstream dependency (Cash App Service) failed during payment capture, likely due to transient backend or integration issues. The customer alert points to a data integrity issue (duplicate Okta ID), which can cause application logic failures. The deliveryreceipt error references a SQL syntax error (code 42601), likely from malformed queries or unexpected input. All alerts are from AWS-hosted services in prod2, using Lambda and ECS, and were detected via CloudWatch Logs. The Ok status at alert time means automated recovery or transient resolution occurred, possibly via retries, code fixes, or data correction. No evidence of persistent or systemic failure, and no user tickets suggest limited or no end-user impact. The sequence and timing show independent, short-lived issues across services, not a single root cause. | G11: RACPad Support | H11: Vandana K | M11: BigPanda | N11: BigPanda
A12: INCTEC1591960 | B12: 46054.53 | C12: 3 - Moderate | D12: Closed | E12: BigPanda Incident: cloud2gcdb - Ok | F12: Incident Summary: -------------------------------------------------------- AI-Generated Incident Analysis Resolved: cloud2gcdb Lambda Event Processing Errors Cleared in prod2 (FIELD SYSTEMS) From 18:38:14 to 20:38:10 UTC on Feb 1, 2026, 30 Ok alerts were generated for the prod2-cloud2gcdb-lambda-Cloud2GcdbSubscriptionFilter in the prod2 environment (FIELD SYSTEMS). All alerts indicate resolution of prior event processing errors. No active issues remain, and no user tickets were correlated. Systems are operating normally. Between 18:38:14 and 20:38:10 UTC on Feb 1, 2026, 30 Ok alerts were generated for the prod2-cloud2gcdb-lambda-Cloud2GcdbSubscriptionFilter in the prod2 environment. These Ok alerts indicate that previously detected errors in event processing (POST-PAYMENT, UPDATE-CUSTOMER) have been resolved. No active root cause remains. In AWS Lambda-based event-driven systems, monitoring tools like logzio_custom ingest CloudWatch Logs and generate alerts for error patterns. Ok alerts signify that error conditions (e.g., failed POST-PAYMENT/UPDATE-CUSTOMER events) have cleared. The absence of critical/warning/unknown alerts and the Ok status across all 30 alerts confirm system recovery. The incident's Ok status supersedes individual alert statuses, indicating full resolution. The time sequencing shows a return to normalcy, with no evidence of ongoing or recurring issues. This pattern is typical in serverless architectures, where transient errors are detected, remediated, and then cleared, triggering Ok notifications. | G12: RACPad Support | H12: Vandana K | M12: BigPanda | N12: BigPanda
A13: INCTEC1591962 | B13: 46054.539 | C13: 3 - Moderate | D13: Closed | E13: BigPanda Incident: sfcc - Ok | F13: Incident Summary: -------------------------------------------------------- AI-Generated Incident Analysis Warning: Application Errors in prod2-sfcc-store-inventory-delta-events Lambda Due to Missing Inventory Data (Flapping) On Feb 1, 2026, at 08:27 UTC, two Warning alerts for 'prod2-sfcc-store-inventory-delta-events-lambda-PublishStoreInventoryUpdatestoSFCCSubscriptionFilter' in prod2 signaled repeated 500 errors due to missing Inventory and InventoryPrice fields. The incident is flapping, with 2 warnings and 1 ok alert, affecting the sfcc-store-inventory-delta-events application. At 08:27:12 UTC on Feb 1, 2026, two Warning alerts were triggered for 'prod2-sfcc-store-inventory-delta-events-lambda-PublishStoreInventoryUpdatestoSFCCSubscriptionFilter' in prod2, both with statusCode 500 and error: 'Inventory and InventoryPrice is required'. This indicates the root cause is missing required fields in event payloads for this Lambda function. The Ok alert at 08:29:14 UTC is for a different application and is not causal. AWS Lambda functions process events and require specific payload fields to execute business logic. The error 'Inventory and InventoryPrice is required' with statusCode 500 means the Lambda could not process events due to missing data, resulting in application-level failures. HTTP 500 errors indicate server-side issues, not client or network faults. The simultaneous occurrence of two identical warnings for the same Lambda and error message at 08:27:12 UTC confirms a systemic issue with event payloads, not a transient or isolated error. The incident is flapping, suggesting intermittent resolution or repeated failures, possibly as upstream systems intermittently provide or omit required fields. The Ok alert at 08:29:14 UTC is for a different Lambda and application, with a different error, and does not contribute to the root cause. No user tickets or historical actions are present, so the analysis relies solely on alert evidence. | G13: RACPad Support | H13: Vandana K | M13: BigPanda | N13: BigPanda
A14: INCTEC1591978 | B14: 46054.62 | C14: 3 - Moderate | D14: Closed | E14: BigPanda Incident: campaignstatistics - Ok | F14: Incident Summary: -------------------------------------------------------- AI-Generated Incident Analysis Resolved Data Integrity Error in campaignstatistics Application (prod2/AWS) On Feb 1, 2026, at 20:48:10 UTC, two Ok alerts signaled resolution of a prior data integrity error in the 'campaignstatistics' application (prod2, AWS). The issue involved a missing customer_id causing database errors in Lambda processes. No ongoing impact; incident is resolved. Total alerts: 2 Ok. At 20:48:10 UTC on Feb 1, 2026, two Ok alerts were generated for the 'campaignstatistics' application in prod2/AWS. Both referenced prior 500 errors due to a PostgreSQL foreign key violation (missing customer_id in 'customer' table). The root cause was a transient data integrity issue, now resolved, affecting related Lambda processes. PostgreSQL error 23503 indicates a foreign key violation, meaning a referenced customer_id was missing in the 'customer' table when inserting/updating 'account_management_activity'. This enforces referential integrity, preventing orphaned records. The alerts' Ok status and identical timestamps show the application recovered after the transient data issue was resolved, likely by correcting the missing customer or adjusting the data flow. The use of AWS Lambda functions suggests event-driven processing, where such errors can occur if upstream data is incomplete or delayed. No ongoing alerts or tickets indicate the issue was self-healing or remediated promptly. | G14: RACPad Support | H14: Divya P2 | M14: BigPanda | N14: BigPanda
A15: INCTEC1591981 | B15: 46054.655 | C15: 3 - Moderate | D15: Closed | E15: BigPanda Incident: cloud2gcdb - Ok | F15: Incident Summary: -------------------------------------------------------- AI-Generated Incident Analysis Resolved: Transient POST-PAYMENT Processing Errors in prod2-cloud2gcdb-lambda-Cloud2GcdbSubscriptionFilter (Production) On Feb 1, 2026, between 21:38 and 22:38 UTC, 20 Ok-status alerts reported and resolved errors in POST-PAYMENT event processing by the prod2-cloud2gcdb-lambda-Cloud2GcdbSubscriptionFilter function in the prod2 environment. No ongoing issues or user impact remain. All alerts are cleared. Between 21:38:10 and 22:38:12 UTC on Feb 1, 2026, 20 alerts reported errors processing POST-PAYMENT events in the prod2-cloud2gcdb-lambda-Cloud2GcdbSubscriptionFilter function across multiple stores. All alerts are now Ok, indicating the errors were transient and have been resolved. No ongoing impact is present. AWS Lambda functions, such as prod2-cloud2gcdb-lambda-Cloud2GcdbSubscriptionFilter, process events asynchronously. Errors in event processing (e.g., POST-PAYMENT) can trigger alerts if exceptions occur. The Ok status means the function recovered or the error condition cleared. The 1-hour gap between alert groups suggests a batch or periodic process. No critical or warning alerts remain, confirming resolution. The absence of flapping and the Ok incident status further support that the issue was transient and not systemic. No service desk tickets or historical actions indicate user impact, so the root cause was likely a temporary processing anomaly, now cleared. | G15: RACPad Support | H15: Vandana K | M15: BigPanda | N15: BigPanda
A16: INCTEC1591999 | B16: 46054.739 | C16: 3 - Moderate | D16: Closed | E16: BigPanda Incident: cloud2gcdb - Ok | F16: Incident Summary: -------------------------------------------------------- AI-Generated Incident Analysis Resolved: cloud2gcdb Lambda POST-PAYMENT Event Processing Errors Cleared in prod2 On February 1, 2026, at 23:38:11 UTC, 10 Ok alerts indicated resolution of prior errors in the prod2-cloud2gcdb-lambda-Cloud2GcdbSubscriptionFilter function processing POST-PAYMENT events for FIELD SYSTEMS in the prod2 environment. No ongoing issues or user impact detected; all systems are now normal. At 2026-02-01T23:38:11.000Z, 10 alerts (all Ok) reported previously detected errors in the prod2-cloud2gcdb-lambda-Cloud2GcdbSubscriptionFilter function while processing POST-PAYMENT events across multiple stores. The Ok status and identical timestamps confirm the underlying issue was resolved before this incident snapshot. AWS Lambda functions, like prod2-cloud2gcdb-lambda-Cloud2GcdbSubscriptionFilter, process events (here, POST-PAYMENT) and can emit errors if processing fails. CloudWatch Logs (cwl) and logzio_custom monitor these errors, generating alerts. The Ok status means the error condition cleared—likely via code fix, input correction, or transient issue resolution. Simultaneous Ok alerts across stores indicate a systemic issue was resolved, not isolated to a single store. No critical/warning alerts or ongoing errors support that the Lambda function is now operating normally. The absence of flapping and tickets further confirms stability. Thus, the root cause was a resolved, short-lived error in Lambda event processing. | G16: RACPad Support | H16: Vandana K | M16: BigPanda | N16: BigPanda
A17: INCTEC1592007 | B17: 46054.78 | C17: 3 - Moderate | D17: Closed | E17: BigPanda Incident: cloud2gcdb - Ok | F17: Incident Summary: -------------------------------------------------------- AI-Generated Incident Analysis Resolved: Transient POST-PAYMENT Processing Errors in cloud2gcdb Lambda (prod2 Environment) From Feb 1, 2026, 23:38 UTC to Feb 2, 2026, 00:38 UTC, 20 resolved alerts reported POST-PAYMENT event processing errors in the 'cloud2gcdb' Lambda ('prod2-cloud2gcdb-lambda-Cloud2GcdbSubscriptionFilter') in the 'prod2' environment. All alerts are Ok; no ongoing impact. No user tickets or flapping detected. Between 23:38:11 UTC and 00:38:11 UTC (Feb 1–2, 2026), 20 alerts reported errors processing POST-PAYMENT events in the 'prod2-cloud2gcdb-lambda-Cloud2GcdbSubscriptionFilter' Lambda for 'cloud2gcdb' in 'prod2'. All alerts are now Ok, indicating the errors were transient and self-resolved. No ongoing issues detected. AWS Lambda functions process events asynchronously; errors can occur due to transient issues (e.g., downstream service latency, temporary data inconsistencies, or resource contention). The alerts, all referencing POST-PAYMENT event errors, suggest a brief disruption. Since all alerts are now Ok and no new errors are reported, the Lambda or its dependencies recovered automatically, consistent with cloud-native error handling and retry mechanisms. The lack of critical or warning alerts, and the absence of flapping, further supports that the incident was self-healing and did not require manual intervention. | G17: RACPad Support | H17: Vandana K | M17: BigPanda | N17: BigPanda
A18: INCTEC1592010 | B18: 46054.784 | C18: 3 - Moderate | D18: Closed | E18: BigPanda Incident: processpayment - Ok (Flapping) | F18: Incident Summary: -------------------------------------------------------- AI-Generated Incident Analysis Resolved Transient 500 Errors in processpayment, customer, and deliveryreceipt Applications (prod2/AWS) On Feb 1, 2026, nine Ok-status alerts were generated for processpayment, customer, and deliveryreceipt apps in prod2 (AWS). Earlier, these services experienced transient 500 errors (payment, data, SQL issues), but all were resolved before alerting. No ongoing impact, no user tickets, and all systems are currently healthy. Between 16:45:09Z and 18:20:13Z on Feb 1, 2026, multiple applications in prod2 (AWS) experienced transient 500 errors: processpayment (Cash App Service internal errors), customer (duplicate Okta ID), and deliveryreceipt (UploadReceiptsService SQL error). All issues resolved before alerting, as indicated by Ok status at alert times. HTTP 500 errors indicate server-side failures. For processpayment, the error 'PP_CASHAPP_500' suggests a downstream dependency (Cash App Service) failed during payment capture, likely due to transient backend or integration issues. The customer alert points to a data integrity issue (duplicate Okta ID), which can cause application logic failures. The deliveryreceipt error references a SQL syntax error (code 42601), likely from malformed queries or unexpected input. All alerts are from AWS-hosted services in prod2, using Lambda and ECS, and were detected via CloudWatch Logs. The Ok status at alert time means automated recovery or transient resolution occurred, possibly via retries, code fixes, or data correction. No evidence of persistent or systemic failure, and no user tickets suggest limited or no end-user impact. The sequence and timing show independent, short-lived issues across services, not a single root cause. | G18: RACPad Support | H18: Vandana K | M18: BigPanda | N18: BigPanda
A19: INCTEC1592020 | B19: 46054.822 | C19: 3 - Moderate | D19: Closed | E19: BigPanda Incident: cloud2gcdb - Ok | F19: Incident Summary: -------------------------------------------------------- AI-Generated Incident Analysis Resolved: cloud2gcdb Lambda Event Processing Errors Cleared in prod2 Across Multiple Stores From Feb 1, 2026, 23:38 UTC to Feb 2, 2026, 01:38 UTC, 30 Ok-status alerts were generated for 'cloud2gcdb' in 'prod2', referencing Lambda 'Cloud2GcdbSubscriptionFilter' errors across multiple stores. All issues have cleared, with no ongoing impact. No user tickets or flapping detected. Between 23:38:11 UTC on Feb 1, 2026, and 01:38:08 UTC on Feb 2, 2026, 30 Ok-status alerts were generated for 'cloud2gcdb' in 'prod2', referencing errors in the Lambda 'Cloud2GcdbSubscriptionFilter' across multiple stores. All alerts indicate the issue has cleared; no active errors remain. The root cause was likely a transient error in event processing by the Lambda, now resolved. AWS Lambda functions like 'Cloud2GcdbSubscriptionFilter' process events (here, POST-PAYMENT) and can fail due to transient issues (e.g., downstream service unavailability, malformed events, or temporary resource constraints). The alerts, sourced from CloudWatch Logs, show error messages but all have status Ok, meaning the monitoring system detected the error condition was resolved before the incident closed. The clustering of alert times suggests a batch of errors occurred, but the absence of critical/warning/unknown alerts and the final Ok status confirm recovery. The distributed nature (multiple store_numbers) implies either a systemic but short-lived issue or a batch of problematic events. No evidence points to persistent or underlying infrastructure faults. The lack of flapping and the Ok status across all alerts further support that the Lambda's error state was transient and has been remediated, either automatically or via a fix. | G19: RACPad Support | H19: Vandana K | M19: BigPanda | N19: BigPanda
... A24: INCTEC1592041 | B24: 46054.977 | C24: 3 - Moderate | D24: Closed | E24: BigPanda Incident: cloud2gcdb - Ok | F24: Incident Summary: -------------------------------------------------------- AI-Generated Incident Analysis Resolved: cloud2gcdb Lambda POST-PAYMENT Event Processing Errors Cleared in prod2 On Monday, February 2, 2026, at 5:21:07 AM UTC, four 'Ok' alerts for the 'cloud2gcdb' Lambda in 'prod2' (stores 08569, 08687, 08717) indicated resolution of prior POST-PAYMENT event processing errors. All alerts cleared simultaneously, confirming the application has returned to normal operation. No further action is required. At 05:21:07 UTC on February 2, 2026, four 'Ok' alerts were generated for the 'cloud2gcdb' Lambda function in 'prod2', each referencing prior errors processing POST-PAYMENT events for different stores. The simultaneous 'Ok' status indicates that earlier errors were resolved and normal processing resumed. No ongoing issues remain. AWS Lambda functions process events asynchronously, with errors often logged to CloudWatch Logs. The 'cwl' alerts here, all marked 'Ok' at the same timestamp, suggest that previous POST-PAYMENT event processing errors were detected and have since cleared. The Lambda's recovery is reflected by the 'Ok' status, indicating successful subsequent executions. No new errors or warnings are present, and the incident status confirms resolution. The use of CloudWatch Logs for alerting is standard in serverless architectures, and the simultaneous clearance across multiple stores implies a systemic, but transient, issue—possibly a brief service or dependency disruption that self-resolved. The absence of correlated tickets or ongoing alerts further supports that the root cause was a temporary error in the Lambda's event processing, now remediated. | G24: RACPad Support | H24: Divya P2 | M24: BigPanda | N24: BigPanda
A25: INCTEC1592055 | B25: 46055.066 | C25: 4 - Low | D25: Closed | E25: RE: LEVEL 0 Customer - Junia Sohs - 3074150-RACPAD | F25: From: Katherine Fang <Katherine.Fang@Rentacenter.com> Sent: Saturday, January 31, 2026 3:53 AM To: RACPad Support <RACPadSupport@rentacenter.com> Cc: Seema Rani <Seema.Rani@Rentacenter.com>; Caroline Zhu <Caroline.Zhu@Rentacenter.com>; OperationsSupport <OperationsSupport@Rentacenter.com> Subject: LEVEL 0 Customer - Junia Sohs - 3074150 Hi RACPAD team, We have a customer who is a Level 0 customer but is unable to create a phone agreement. Could you please check this on your end? Thank you! Katherine From: OperationsSupport <OperationsSupport@Rentacenter.com<mailto:OperationsSupport@Rentacenter.com>> Sent: Friday, January 30, 2026 10:31 AM To: Caroline Zhu <Caroline.Zhu@Rentacenter.com<mailto:Caroline.Zhu@Rentacenter.com>>; Katherine Fang <Katherine.Fang@Rentacenter.com<mailto:Katherine.Fang@Rentacenter.com>> Subject: FW: LEVEL 0 Customer - Junia Sohs - 3074150 Based on the expiration date of the DE, it looks like the customer is level 0, but can't add a phone. Can you look at this customer? Mark Bassett Sr. Mgr. Ops Support From: Store 00684 <Store.00684@rentacenter.com<mailto:Store.00684@rentacenter.com>> Sent: Thursday, January 29, 2026 4:27 PM To: OperationsSupport <OperationsSupport@Rentacenter.com<mailto:OperationsSupport@Rentacenter.com>> Cc: Brian Stewart <Brian.Stewart@rentacenter.com<mailto:Brian.Stewart@rentacenter.com>> Subject: Re: LEVEL 0 Customer In the bottom right circled in red is what it says just now when I tried to special order it. ________________________________ From: OperationsSupport <OperationsSupport@Rentacenter.com<mailto:OperationsSupport@Rentacenter.com>> Sent: Thursday, January 29, 2026 1:18 PM To: Store 00684 <Store.00684@rentacenter.com<mailto:Store.00684@rentacenter.com>> Cc: Brian Stewart <Brian.Stewart@rentacenter.com<mailto:Brian.Stewart@rentacenter.com>> Subject: RE: LEVEL 0 Customer Customer record shows to be a level 0 in RACPAD based on the DE expiration of 03-29-2026. Mark Bassett Sr. Mgr. Ops Support From: Store 00684 <Store.00684@rentacenter.com<mailto:Store.00684@rentacenter.com>> Sent: Thursday, January 29, 2026 4:09 PM To: OperationsSupport <OperationsSupport@Rentacenter.com<mailto:OperationsSupport@Rentacenter.com>> Cc: Brian Stewart <Brian.Stewart@rentacenter.com<mailto:Brian.Stewart@rentacenter.com>> Subject: LEVEL 0 Customer Good afternoon, I am trying to rent this customer a iPhone 17 Pro-Max Silver 256gb Model# NW00107 in Sales force it shows she is Level-0 But when I try and customer special order it in Rac-Pad it says customer is not eligible, can you help me get this customer's phone ordered by updating her profile in Rac-Pad to match what it shows in Sales Force ? Rent-A-Center 00684 4240 Old Seward Highway Ste 24 Anchorage, AK 99503 907-290-5252 | G25: RACPad Support | H25: Jitheesha Thankachan | I25: RACPAD - other | M25: Customer | N25: Customer level change request
A26: INCTEC1592060 | B26: 46055.106 | C26: 3 - Moderate | D26: Closed | E26: BigPanda Incident: sfcc - Ok | F26: Incident Summary: -------------------------------------------------------- AI-Generated Incident Analysis Resolved: Server-Side Errors in prod2 Affecting sfcc-store-inventory-delta-events and tcpaeventsubscribe On February 2, 2026, three server-side errors were detected in the 'prod2' environment: two in 'sfcc-store-inventory-delta-events' and one in 'tcpaeventsubscribe', all related to AWS Lambda functions. Errors were due to missing required data or processing failures. All alerts are now resolved, and services are operating normally. Between 08:27:07 and 08:44:13 UTC on February 2, 2026, three server-side errors (HTTP 500) were detected in the 'prod2' environment. Two alerts for 'sfcc-store-inventory-delta-events' lambda reported missing 'Inventory' and 'InventoryPrice' fields, preventing event processing. The third alert for 'tcpaeventsubscribe' lambda indicated a processing error in 'ProcessTcpaEventsEntdbService'. All alerts are now resolved, indicating the underlying data or service issues were transient or remediated. The root cause was missing or malformed event data for the first two alerts and a processing failure for the third, all within the same production environment. Multiple AWS Lambda functions in a shared environment experienced temporary HTTP 500 errors due to incomplete event data, likely from a systemic upstream issue, but the problem resolved quickly without user impact. | G26: RACPad Support | H26: Divya P2 | M26: BigPanda | N26: BigPanda
A27: INCTEC1592088 | B27: 46055.312 | C27: 4 - Low | D27: Closed | E27: RACPAD - Cash Management | Drop Reconciliation | | F27: Drop Reconciliation is not coming up for 01/31/26 to complete. EMP name :Henry Goodman2 EMP ID : 104228 | G27: RACPad Support | H27: Syeda Asfiya | I27: RACPAD - Cash Management | M27: Cash Management | N27: Drop reconciliation issue
A28: INCTEC1592104 | B28: 46055.333 | C28: 3 - Moderate | D28: Closed | E28: BigPanda Incident: sfcc-store-inventory-delta-events - Ok | F28: Incident Summary: -------------------------------------------------------- AI-Generated Incident Analysis Resolved Server Errors in AWS Lambda Functions for sfcc-store-inventory-delta-events and tcpaeventsubscribe (prod2) On February 2, 2026, three server error alerts (all now resolved) were detected in AWS Lambda functions for 'sfcc-store-inventory-delta-events' and 'tcpaeventsubscribe' in the 'prod2' environment. Errors involved missing required data and processing failures. No ongoing issues or user impact are present. Between 08:27:07 and 08:44:13 UTC on February 2, 2026, three server error alerts (statusCode 500) were triggered for AWS Lambda functions in the 'prod2' environment. Two alerts for 'sfcc-store-inventory-delta-events' indicated missing 'Inventory and InventoryPrice' data, while one for 'tcpaeventsubscribe' showed a processing error. All issues are now resolved. HTTP 500 errors in AWS Lambda functions typically indicate unhandled exceptions or failed dependencies. The 'sfcc-store-inventory-delta-events' alerts show missing required fields ('Inventory' and 'InventoryPrice'), suggesting upstream data validation or integration issues. The 'tcpaeventsubscribe' alert references a processing error, likely due to similar data or service dependencies. Both functions are event-driven, relying on correct input payloads and downstream service availability. The close timing and shared environment suggest a transient data or integration issue, now resolved as all alerts are 'Ok'. No evidence of persistent or systemic failure is present, and no user tickets corroborate ongoing impact. | G28: RACPad Support | H28: Vandana K | M28: BigPanda | N28: BigPanda
A29: INCTEC1592117 | B29: 46055.352 | C29: 4 - Low | D29: Closed | E29: Getting 4 digits PIN code error while trying to make payment in RacPad. | F29: User name- Shaquile VelezLaureano Emp Id- 100929 Contact number- (939) 312-3754 Email id- Store-04067 Issue- Getting 4 digits PIN code error while trying to make payment in RacPad. | G29: RACPad Support | H29: Sreenivasa Ks | I29: RACPAD - Payment | M29: Admin | N29: PIN reset
A30: INCTEC1592127 | B30: 46055.369 | C30: 4 - Low | D30: Closed | E30: RACPAD - Cash Management | Drop Reconciliation | | F30: tried to do drop reconciliation showing my drop a eod drop and another store drop all combined with my drop. | G30: RACPad Support | H30: Syeda Asfiya | I30: RACPAD - Cash Management | M30: Cash Management | N30: Drop reconciliation issue
A31: INCTEC1592453 | B31: 46055.742 | C31: 4 - Low | D31: Closed | E31: RACPAD - Payment | Customer Refund | | F31: Customer Name: JOHNATHAN JERNIGAN Last 4 of Card Used: 6737 Exact Amount of Refund: 393.93 Exact Date of Refund: 08/29/2025,10/01/2025,10/08/2025,10/15/2025,10/22/2025,10/29/2025,11/05/2025,11/12/2025,11/19/2025,11/26/2025,12/03/2025, 12/10/2025,12/17/2025,12/24/2025,12/31/2025,01/07/2026,01/14/2026,01/21/2026 Agreement or Receipt #: 8173153532 Detailed Description of Issue: CUSTOMER SAID HE DID NOT RECEIVE MERCHANDISE ============================================================================================================================ Co-worker name: Ashley Hatcher Employee ID: 134725 Store: 00850 Customer name: Jonathan Jernigan Customer ID: 113332362 Receipt #: 455652295, 455018278, 454355868, 453705584, 452976660, 452356408, 451677108, 450991160, 450277754, 449551804, 448897633, 448216822, 447581320, 446844403, 446200269, 445541589, 444878965, 444111102, 440856084 Total Amount Needs to be refunded: $267.12 Issue: CW mentioned merchandise is not received by the customer but the amount is getting dedicated from the customer. Need this amount refunded to the customer. Need help with this. | G31: RACPad Support | H31: shruthika c | I31: RACPAD - Payment | K31: PRB0044395 | M31: Payment | N31: Customer refund | O31: Reccurring
A32: INCTEC1592154 | B32: 46055.405 | C32: 3 - Moderate | D32: Closed | E32: BigPanda Incident: customer - Ok | F32: Incident Summary: -------------------------------------------------------- AI-Generated Incident Analysis Resolved: Transient Backend and Database Errors Across Multiple AWS Production Services On Feb 2, 2026, 15 alerts (all Ok) were generated for AWS-hosted prod2 services, including customer, agreementcreate, processpayment, and others. Alerts referenced prior backend/database errors and network issues, but all services have since recovered. No flapping or open issues remain. No user tickets correlated. Between 15:37 and 17:32 UTC on Feb 2, 2026, multiple AWS-hosted production services (customer, postcommitment, agreementcreate, etc.) experienced transient errors (HTTP 500/400, DB errors, connection resets). All alerts now report Ok, indicating the underlying issues—likely temporary backend/database or integration failures—have been resolved. The alerts show a pattern of transient backend failures: HTTP 500/400 errors, database constraint violations (e.g., missing customer_id, varchar overflows), and network errors (ECONNRESET). These are typical in distributed cloud-native architectures where microservices interact with databases and external APIs. The errors' resolution (all Ok) suggests either a temporary outage or a successful remediation (e.g., DB failover, service restart, or network recovery). The diversity of affected services and error types points to a shared infrastructure or integration point (e.g., database cluster, network segment, or API gateway) as the likely root cause. No ongoing symptoms or flapping are present, confirming stability. | G32: RACPad Support | H32: Vandana K | M32: BigPanda | N32: BigPanda
A33: INCTEC1592612 | B33: 46056.379 | C33: 4 - Low | D33: Closed | E33: RACPAD - Payment | Customer Refund | | F33: Customer Name: Clyde Haines Last 4 of Card Used: cash Exact Amount of Refund: 99.39 Exact Date of Refund: 02/03/2026 Agreement or Receipt #: 455817650 Detailed Description of Issue: Was supposed to be put in as a money order, MO# 22-114535080 which has been put on suspense on the account until the $99.36 payment is removed | G33: RACPad Support | H33: shruthika c | I33: RACPAD - Payment | K33: PRB0044395 | M33: Payment | N33: Customer refund
A34: INCTEC1592172 | B34: 46055.418 | C34: 4 - Low | D34: Closed | E34: RACPAD - Customer | Customer - Other | | F34: Funds pulled from customer's account 2 times. There is no receipt showing on customer's account. Customer ID: 01-31-2026 Customer Name: 114654331 Date and Time Issue Was Occured: 2026-01-31 10:00:27 | G34: RACPad Support | H34: dazel dsouza | I34: RACPAD - Customer | M34: Payment | N34: Customer charged multiple times
A35: INCTEC1592182 | B35: 46055.43 | C35: 3 - Moderate | D35: Closed | E35: BigPanda Incident: cloud2gcdb - Ok | F35: Incident Summary: -------------------------------------------------------- AI-Generated Incident Analysis Resolved: cloud2gcdb Lambda Event Processing Errors Cleared in prod2 Environment On Feb 2, 2026, 29 Ok alerts were generated for the 'cloud2gcdb' application (Lambda: prod2-cloud2gcdb-lambda-Cloud2GcdbSubscriptionFilter) in the 'prod2' environment, across multiple stores. All previously detected errors in event processing have been resolved. No active issues remain. Between 16:13:13 and 17:40:10 UTC on Feb 2, 2026, 29 Ok-status alerts were generated for 'prod2-cloud2gcdb-lambda-Cloud2GcdbSubscriptionFilter' in the 'cloud2gcdb' app. These Ok alerts indicate that prior errors in processing various event types across multiple stores have been resolved. No active or causal issues remain. AWS Lambda functions, such as 'prod2-cloud2gcdb-lambda-Cloud2GcdbSubscriptionFilter', process events (e.g., POST-PAYMENT) and can emit errors if downstream systems or data are unavailable or malformed. The Ok status of all alerts, clustered at three timestamps, suggests that previous errors (likely due to transient issues in event processing or dependencies) have cleared. The monitoring system (logzio_custom via CloudWatch Logs) detected the return to normal operation, generating Ok alerts. No new errors or warnings are present, and the incident status is Ok, confirming resolution. The absence of flapping and service desk tickets further supports that the Lambda function and its integrations are now stable. | G35: RACPad Support | H35: Vandana K | M35: BigPanda | N35: BigPanda
A36: INCTEC1592188 | B36: 46055.437 | C36: 4 - Low | D36: Closed | E36: RACPAD - Agreement | Unable to create an Agreement | | F36: Trying to write agreement, keeps telling me that "Invalid inventoryID or inventroyID is not associated with store" Agreement Number: 00000000000 Customer ID: 111648466 Customer Name: Brandon Estep Date and Time Issue Was Occured: 2026-02-02 10:19:07 Store number: 02156 - MORRISTOWN-2171 AJ HWY - A - M0202 - R0070 - S08 - RACUSA Coworker name and ID: Jordan Musslewhite 350817 Customer name and number: Brandon Estep 111648466 Computer name: 02156-3CM31D3 IP address: 10.108.107.44 Issue description: Trying to write agreement, keeps telling me that "Invalid inventoryID or inventroyID is not associated with store" Steps taken to arrive at problem: Time of occurrence (Recreate the issue and notate the time if needed): 2026-02-02 10:19:07 Screen shot required: YES | G36: RACPad Support | H36: atulashok shinde | I36: RACPAD - Agreement | M36: Inventory | N36: Invalid inventoryId error
A37: INCTEC1592199 | B37: 46055.444 | C37: 4 - Low | D37: Closed | E37: RacPad | Autopay Issue | F37: customers not receiving enrollement auto pay text | G37: RACPad Support | H37: Jitheesha Thankachan | I37: RACPAD - other | M37: Customer | N37: AutoPay
A38: INCTEC1592210 | B38: 46055.45 | C38: 4 - Low | D38: Closed | E38: Racpad and other Apps was working very slow | F38: Issue : Racpad and Apps was working very slow its just loading EMP name : Britney Richardson EMP ID : 164935 Store Number : 02895 Router ID : MX68CW_NA Computer Name : 02895-7QNCID3 IP Address: 10.111.78.60 | G38: RACPad Support | H38: muniraja p | I38: Store Network | M38: Store | N38: RACPAD slowness
A39: INCTEC1592214 | B39: 46055.452 | C39: 4 - Low | D39: Closed | E39: RACPAD - Payment | CCCB | | F39: Customer stated that She has checked with her back and there has been no charge backs on her account that every payment has gone through. Customer will bring in her Bank statements for last two months Agreement Number: 479680609 Customer ID: 6061344 Customer Name: Steven Peacock Date and Time Issue Was Occured: 2025-12-18 10:47:37 | G39: RACPad Support | H39: Hemanth Mangalore | I39: RACPAD - Payment | M39: Payment | N39: CCCB related query
A40: INCTEC1592231 | B40: 46055.464 | C40: 4 - Low | D40: Closed | E40: RACPAD-cash Box Issue | F40: Store number: 01201 Coworker name and ID: Victor CentenoII || 363211 Customer name and number: - Computer name: 01201-DX7BV93 Issue description: issue with Deposit amount or cash Box RACPAD Steps taken to arrive at problem: RACPAD | G40: RACPad Support | H40: shweta wadhwa | I40: RACPAD - Cash Management | M40: Cash Management | N40: Cash box issue
A41: INCTEC1592753 | B41: 46056.534 | C41: 4 - Low | D41: Closed | E41: RACPAD - Payment | Customer Refund | | F41: Customer Name: Makwayah Shepperson Last 4 of Card Used: 4424 Exact Amount of Refund: $129.17 Exact Date of Refund: 02/03/2026 Agreement or Receipt #: 455771395 Detailed Description of Issue: This customer placed an order for a Midnight Madness sectional with us. We attempted the delivery today and found the sectional didn't fit in the customer's home. The customer then found an item that she was interested in that would fit in the home and we decided to do a RAC exchange for the product since she had put $129.17 down at the start of the original agreement. We scheduled the carryout for the new couch with her and then she called back later and requested to cancel the order and requested a full refund since she hadn't actually received any products. I attempted to preform the refund however it only allowed me to refund the club membership payment not the rental amount so I didn't complete that refund. I attached a copy of the original receipt. Please assist. Thank you in advance for any assistance in this matter! | G41: RACPad Support | H41: Abhishek TV | I41: RACPAD - Payment | K41: PRB0044395 | M41: Payment | N41: Customer refund | O41: Reccurring
A42: INCTEC1592238 | B42: 46055.468 | C42: 4 - Low | D42: Closed | E42: RACPAD - Agreement | Agreement - Other | | F42: Customer order, order came in, i went to activate it, the accept payment button is greyed out and i can not move on from it. Agreement Number: 8174528433 Customer ID: 100016228355 Customer Name: Jerry Watson Date and Time Issue Was Occured: 2026-01-29 11:13:21 | G42: RACPad Support | H42: atulashok shinde | I42: RACPAD - Agreement | M42: Agreement | N42: Accept Payment button greyed out
A43: INCTEC1592253 | B43: 46055.485 | C43: 4 - Low | D43: Closed | E43: Racpad Customer | F43: CW need a report that shows customer contact number that is recently changed on racpad | G43: RACPad Support | H43: dazel dsouza | I43: RACPAD - Customer | M43: Customer | N43: Data request
A44: INCTEC1592257 | B44: 46055.487 | C44: 3 - Moderate | D44: Closed | E44: BigPanda Incident: campaignstatistics - Ok | F44: Incident Summary: -------------------------------------------------------- AI-Generated Incident Analysis Resolved: campaignstatistics Lambda Foreign Key Violation in prod2 (AWS) On February 2, 2026, at 17:36:15 UTC, two alerts for the 'campaignstatistics' application in the 'prod2' AWS environment reported a previously resolved database error. The issue involved a foreign key violation in a Lambda function, but the system is now healthy. No user tickets or ongoing impact detected. At 17:36:15 UTC on February 2, 2026, two alerts reported a resolved state for the 'campaignstatistics' application in 'prod2' (AWS). The underlying issue was a database foreign key violation (PostgreSQL error 23503) in the 'ProcessCampaignStatsService' Lambda, caused by a missing 'customer_id' in the 'customer' table. The alerts indicate the error condition has cleared. PostgreSQL error 23503 signals a foreign key violation, meaning an operation tried to reference a non-existent 'customer_id' in the 'customer' table. This is enforced by relational database integrity constraints. The Lambda function 'ProcessCampaignStatsSubscriptionFilter' likely attempted to insert or update 'account_management_activity' with a 'customer_id' not present in 'customer', triggering a 500 error. The alerts, both marked 'Ok', confirm the error condition was transient and has since resolved, suggesting either the missing customer was added or the process was corrected. No flapping or ongoing issues are present, and no user tickets indicate broader impact. | G44: RACPad Support | H44: Vandana K | M44: BigPanda | N44: BigPanda
...

Sheet Issue wise Summary
A1: Type of Issue | B1: Incidents linked to this issue | C1: Issue Description | D1: One time/Reccurring | E1: Problem associated? | F1: Problem | G1: Automation/Shift Left | H1: Remarks
A2: BigPanda | B2: 731 | C2: Big Panda tickets
A3: Unable to take payments | B3: 64 | C3: Most of these tickets were created due to a worldpay outage | D3: One time
A4: Access | B4: 59 | C4: Access related issues | D4: Recurring | E4: Yes | F4: PRB0045218
A5: Unable to receive the purchase order | B5: 44 | C5: Due to missing prices stores will not be able to receive PO. Once the prices are published this will be resolved. | D5: Recurring
A6: Payment not reflecting in RACPAD | B6: 44 | C6: Customer account will be deducted but the payment will not be refelcted in RACPAD. | D6: Recurring | G6: Shared with LEAP team | H6: Check with ESS team if API is present for accesing IQ portal
A7: AutoPay | B7: 38 | C7: Customers unable to enroll into AutoPay | D7: Recurring | E7: Yes | G7: Shared with LEAP team
A8: Unable to create an Agreement | B8: 33 | C8: Stores were unable to create an agreement due to a Change rollback. | D8: One time
A9: Cancel the Manual PO | B9: 33 | C9: Request to cancel Manual PO | D9: Recurring | E9: Yes | F9: PRB0045846
A10: PIN reset | B10: 25 | C10: Request to Reset CW PIN | D10: Recurring | G10: Need to discuss with Business if the RESET PIN option can be provided to user itself.
A11: Customer refund | B11: 24 | C11: Customer has not received the refund | D11: Recurring | E11: Yes | F11: PRB0044395 | H11: check with Data Services team on this pattern
A12: Agreement switch-out completed, but inventory remains in "Pending Switch Out" status | B12: 21 | C12: Agreement switch-out completed, but inventory remains in "Pending Switch Out" status | D12: Recurring | E12: Yes | F12: PRB0045906
A13: Unable to print service sheet | B13: 21 | C13: Store were unable to print service sheet. This issue was caused due to a release | D13: One time
A14: There was an error processing your request popup | B14: 20 | C14: When taking payments the store will recievie a popup saying there was an error | D14: One time
A15: Customer not eligible for reward error | B15: 18 | C15: Stores were getting an error popup saying "Customer not eligible for reward error" | D15: One time
A16: Unable to confirm delivery | B16: 16 | C16: CW is unable to confirm delivery. This can be due to missing customer contact details. Once updated they will be able to confirm delivery | D16: Recurring | G16: Shift left | H16: Create a problem ticket
A17: Unable to add package items | B17: 15 | C17: Stores were unable to add items to package. This issue was caused due to a release | D17: One time
A18: Level 0 customer cannot order phone | B18: 14 | C18: A customer who is level 0 cannot order a mobile phone | D18: Recurring | G18: FIxed by dev
A19: Error in RmsReserveOrderService | B19: 12 | C19: When adding an item to create an agreement, "Error in RMSReserveOrderService" message pops up. This can be due to the item being Out of stock | D19: Recurring
A20: Unable to fetch the data | B20: 9 | C20: The fields going blank in Account Management screen with the error as "Unable to fetch the data". This is an intermittent issue | D20: Recurring
A21: Drop reconciliation issue | B21: 8 | C21: Drop related issues | D21: Recurring
A22: Cancel the RMS PO | B22: 8 | C22: Request to cancel the RMS PO. | D22: Recurring | E22: Yes | F22: PRB0045373
A23: Report issues | B23: 8 | C23: Report related issues such as data mismatch etc | D23: Recurring
A24: Void the agreement and change the inventory status to idle | B24: 8 | C24: Request to void the agreement and change the inventory status | D24: Recurring
A25: Incorrect due date | B25: 8 | C25: Due date showing incorrect | D25: Recurring
A26: Customer level change request | B26: 7 | C26: Request to change the level of the customer | D26: Recurring | G26: Shift left
A27: Customer charged multiple times | B27: 7
A28: CCCB related query | B28: 6
A29: Identity link not working | B29: 6
A30: NSF related | B30: 6
A31: This feauture is currently not assigned to you | B31: 6
A32: Unable to take item out of service | B32: 5
A33: Unable to add benefit plus | B33: 5
A34: Payment issue | B34: 5
A35: Incorrect charges | B35: 4
A36: Customer level query | B36: 4
A37: Inventory status change request | B37: 4
A38: Receipt reversal | B38: 3
... A94: Promo start date change | B94: 1

Sheet Issue wise details
A1: Type of Issue | B1: No of tickets | C1: Issue Description | D1: One time/Recurring | E1: Problem Associated? | F1: Problem | G1: Automation/Shift Left | H1: Remarks
A2: BigPanda | B2: 731 | C2: =VLOOKUP(A2,'Issue wise Summary'!A:C,3,FALSE) -> Big Panda tickets
A3: Unable to take payments | B3: 64 | C3: =VLOOKUP(A3,'Issue wise Summary'!A:C,3,FALSE) -> Most of these tickets were created due to a worldpay outage | D3: =VLOOKUP(A3,'Issue wise Summary'!A:D,4,FALSE) -> One time
A4: Access | B4: 59 | C4: =VLOOKUP(A4,'Issue wise Summary'!A:C,3,FALSE) -> Access related issues | D4: =VLOOKUP(A4,'Issue wise Summary'!A:D,4,FALSE) -> Recurring | E4: =VLOOKUP(A4,'Issue wise Summary'!A:E,5,FALSE) -> Yes | F4: =VLOOKUP(A4,'Issue wise Summary'!A:F,6,FALSE) -> PRB0045218
A5: Unable to receive the purchase order | B5: 44 | C5: =VLOOKUP(A5,'Issue wise Summary'!A:C,3,FALSE) -> Due to missing prices stores will not be able to receive PO. Once the prices are published this will be resolved. | D5: =VLOOKUP(A5,'Issue wise Summary'!A:D,4,FALSE) -> Recurring
A6: Payment not reflecting in RACPAD | B6: 44 | C6: =VLOOKUP(A6,'Issue wise Summary'!A:C,3,FALSE) -> Customer account will be deducted but the payment will not be refelcted in RACPAD. | D6: =VLOOKUP(A6,'Issue wise Summary'!A:D,4,FALSE) -> Recurring | G6: =VLOOKUP(A6,'Issue wise Summary'!A:G,7,FALSE) -> Shared with LEAP team | H6: =VLOOKUP(A6,'Issue wise Summary'!A:H,8,FALSE) -> Check with ESS team if API is present for accesing IQ portal
A7: AutoPay | B7: 38 | C7: =VLOOKUP(A7,'Issue wise Summary'!A:C,3,FALSE) -> Customers unable to enroll into AutoPay | D7: =VLOOKUP(A7,'Issue wise Summary'!A:D,4,FALSE) -> Recurring | E7: =VLOOKUP(A7,'Issue wise Summary'!A:E,5,FALSE) -> Yes | G7: =VLOOKUP(A7,'Issue wise Summary'!A:G,7,FALSE) -> Shared with LEAP team
A8: Unable to create an Agreement | B8: 33 | C8: =VLOOKUP(A8,'Issue wise Summary'!A:C,3,FALSE) -> Stores were unable to create an agreement due to a Change rollback. | D8: =VLOOKUP(A8,'Issue wise Summary'!A:D,4,FALSE) -> One time
A9: Cancel the Manual PO | B9: 33 | C9: =VLOOKUP(A9,'Issue wise Summary'!A:C,3,FALSE) -> Request to cancel Manual PO | D9: =VLOOKUP(A9,'Issue wise Summary'!A:D,4,FALSE) -> Recurring | E9: =VLOOKUP(A9,'Issue wise Summary'!A:E,5,FALSE) -> Yes | F9: =VLOOKUP(A9,'Issue wise Summary'!A:F,6,FALSE) -> PRB0045846
