Workbook

Sheet Dump
A1: Number | B1: Priority | C1: Created | D1: Updated | E1: Status | F1: Assigned to | G1: Action | H1: Short Description | I1: Description | J1: Assignment Group | K1: Location | L1: Parent | M1: Caused by Change | N1: Problem | O1: Category | P1: Module | Q1: Type Of Issue | R1: Steps taken to fix
A2: INCTEC1587933 | B2: 4 - Low | C2: 46044.408 | D2: 46051.75 | E2: Closed | F2: Vandana K | G2: RACPAD - other | H2: cannot access RACPad | I2: Employee Kelly Pike, ID#100914 cannot access RACPad | J2: RACPad Support | K2: 03982 - COVINGTON-HWY 278 NE - A - M0136 - R0008 - S07 - RACUSA | N2: PRB0045218 | O2: Incident | P2: Access | Q2: RACPAD Access not available
A3: INCTEC1588121 | B3: 4 - Low | C3: 46044.601 | D3: 46052.542 | E3: Closed | F3: monisha d | G3: RACPAD - Store | H3: Racpad store access 00648 | I3: not allowing me to access anything on racpad Issue : Need a Racpad store access 00648 EMP name : Elijah Bowles EMP ID : 369391 Store number : 00648 | J3: RACPad Support | K3: 00648 - ALTOONA - A - M0288 - R0058 - S08 - RACUSA | M3: CHG0050487 | N3: PRB0045218 | O3: Incident | P3: Access | Q3: RACPAD Access not available
A4: INCTEC1588496 | B4: 4 - Low | C4: 46045.517 | D4: 46052.417 | E4: Closed | F4: Abhishek TV | G4: RACPAD - Store | H4: Racpad store access 04006 | I4: EMP Name : Kaitlyn Crutchfield EMP ID : 324623 Store Number: 04006 Issue: Need a racpad store access of 04006 | J4: RACPad Support | K4: 04006 - GREENVILLE-LAURENS RD - A - M0032 - R0008 - S07 - RACUSA | N4: PRB0045218 | O4: Incident | P4: Access | Q4: RACPAD Access not available
A5: INCTEC1588567 | B5: 4 - Low | C5: 46045.608 | D5: 46052.417 | E5: Closed | F5: Prasanth K | G5: RACPAD - Store | H5: Racpad store access 04159 | I5: Issue: Need a racpad store access of 04159 EMP Name : Quatravious Brown EMP ID : 360579 Store number : 04159 | J5: RACPad Support | K5: 04159 - RIVERA BEACH-BROADWAY - A - M0159 - R0024 - S08 - RACUSA | N5: PRB0045218 | O5: Incident | P5: Access | Q5: RACPAD Access not available
A6: INCTEC1587322 | B6: 4 - Low | C6: 46042.758 | D6: 46054.417 | E6: Closed | F6: Pratik Singar | G6: RACPAD - Store | H6: (No subject) | I6: Good afternoonm , coworker id : 341175 doesn't have access to his racpad , thank you | J6: RACPad Support | K6: 01206 - EAST MIAMI - A - M0158 - R0024 - S08 - RACUSA | N6: PRB0045218 | O6: Incident | P6: Access | Q6: RACPAD Access not available
A7: INCTEC1586770 | B7: 4 - Low | C7: 46041.745 | D7: 46053.458 | E7: Closed | F7: Lalit RameshTurkar | G7: RACPAD - other | H7: 100858@rentacenter.com does not have access to rac pad | I7: 100858@rentacenter.com does not have access to rac pad | J7: RACPad Support | K7: 02309 - PROVO - A - M0234 - R0040 - S07 - RACUSA | N7: PRB0045218 | O7: Incident | P7: Access | Q7: RACPAD Access not available
A8: INCTEC1581790 | B8: 4 - Low | C8: 46029.553 | D8: 46037.25 | E8: Closed | F8: Vandana K | G8: RACPAD - other | H8: access issue | I8: BRADLEY EDWARDS, STORE EMPLOYEE CANNOT LOG IN THE SYSTEM, DOES NOT SHOW AS COWORKER EID: 335567 Name: Bradley Edwards Store: 00822, verified on workday Issue: >CW is not getting store 00822 on racpad, he is still having access to his previous store >CWs needs access to his new assigned store | J8: RACPad Support | K8: 00822 - SAPULPA - A - M0422 - R0080 - S08 - RACUSA | N8: PRB0045218 | O8: Incident | P8: Access | Q8: RACPAD Access not available
A9: INCTEC1590750 | B9: 4 - Low | C9: 46051.451 | D9: 46058.375 | E9: Closed | F9: Abhishek TV | G9: RACPAD - other | H9: Coworker John Keagy (EID 142902) is an employee of 01490. He is a FORMER employee of 01482. He is still able to log into 01482. He has accidentally messed up 01482's final drops twice. Can we please remove his access from 01482? | I9: Coworker John Keagy (EID 142902) is an employee of 01490. He is a FORMER employee of 01482. He is still able to log into 01482. He has accidentally messed up 01482's final drops twice. Can we please remove his access from 01482? | J9: RACPad Support | K9: 01482 - LAWRENCE - A - M0222 - R0080 - S08 - RACUSA | N9: PRB0045218 | O9: Incident | P9: Access | Q9: RACPAD Access not available
A10: INCTEC1588660 | B10: 4 - Low | C10: 46045.787 | D10: 46063.371 | E10: Resolved | F10: Lalit RameshTurkar | G10: RACPAD - Store | H10: Does not have access to RACPad | I10: Does not have access to RACPad Store number: 01021 Coworker name and ID: Ryan Baker Were cache and cookies cleared? Yes Was the computer restarted? Yes Is this happening on one computer or all computers? Example Computer name: 01021-2KT05K3 Computer IP: Steps were taken to arrive at the problem: Time of occurrence (Recreate the issue and notate the time if needed): Screenshot required: YES Required Screenshots: 1 ADP Active Status 1 OKTA Applications 1 of the 'Console' tab 2 for the 'Network' tab (1 of 'current' and 1 of 'menu-and-stores') 1 for the RACPAD screen 1 for the SIMS screen (if applicable) | J10: RACPad Support | K10: 01021 - TUSCALOOSA - A - M0045 - R0070 - S08 - RACUSA | N10: PRB0045218 | O10: Incident | P10: Access | Q10: RACPAD Access not available
A11: INCTEC1587528 | B11: 4 - Low | C11: 46043.427 | D11: 46060.167 | E11: Closed | F11: Sushmitha Sannidhi | G11: Emily | H11: Emily | Emily Metrics | | I11: Emily Metrics unavailable. Says i do not have permission to EMILY . Need access do D0186 stores. 345, 1844, 2838, 647, 2058, 2416, 2723, 3894, 3994, 4598 | J11: RACPad Support | K11: M0186 - N/A - M0186 - R0065 - S08 - RTO | N11: PRB0045218 | O11: Incident | P11: Access | Q11: RACPAD Access not available
A12: INCTEC1588343 | B12: 4 - Low | C12: 46045.344 | D12: 46055.542 | E12: Closed | F12: roopesh pothodi | G12: RACPAD - Store | H12: High Touch-Access | Other | | I12: Brief description of issue RAC PAD not working for Samuel Salley employee #348603 Employee name: Samuel Salley EMPID: 348603 Store: 00830 Call back number: (843) 747-9908 issue: Unable to access RACPAD Detailed issue: >CW reported that she getting an error while trying to access RACPAD. Troubleshooting steps: >Connected through remote. >Verified the same issue from user end. >Tried browser optimization and different browser. >However CW getting the same error (SNIP attached) >Informed CW that will escalate the ticket to the concern Team to check further. | J12: RACPad Support | K12: 00830 - N CHARLESTON-RIVERS - A - M0001 - R0007 - S08 - RACUSA | N12: PRB0045218 | O12: Incident | P12: Access | Q12: RACPAD Access not available
A13: INCTEC1589322 | B13: 4 - Low | C13: 46048.375 | D13: 46051.875 | E13: Closed | F13: praveen panditi | G13: Other | H13: Immediate RACPAD access needed - URGENT | I13: Good morning, We recently had a major ice storm and I need immediate emergency access for RACPAD to be granted to Ron Laney EID 31093 for stores 2974 and 3713. He will need SM access and for as long as we can grant it. Thank You, From: Erik Burgos Soto <erik.burgos@upbound.com> Sent: Monday, January 26, 2026 8:53 AM To: Dustin Hall <Dustin.Hall@rentacenter.com>; Sevicedeskprod <ServiceDeskprod@Rentacenter.com>; ServiceNowSupport <ServiceNowSupport@Rentacenter.com> Cc: Jason Johnson <Jason.Johnson@rentacenter.com> Subject: Re: Immediate RACPAD access needed - URGENT Hello, Thanks for the note, Dustin. The 'ServiceNowSupport@Rentacenter.com' email DL is an unmonitored account for backend system administrators of our ticketing platform. For immediate assistance with active tickets, please contact the Service Desk at 1-800-275-2696. You may also reach them at SupportRequest@Rentacenter.com. Thanks and Best, Erik Burgos ITSM, RPA, ServiceNow, Atlassian Upbound Group, Inc. (UPBD) Service Desk: 1.800.275.2696 > Book time to meet with me From: Dustin Hall <Dustin.Hall@rentacenter.com> Sent: Monday, January 26, 2026 8:48 AM To: Sevicedeskprod <ServiceDeskprod@Rentacenter.com>; ServiceNowSupport <ServiceNowSupport@Rentacenter.com> Cc: Jason Johnson <Jason.Johnson@rentacenter.com> Subject: Immediate RACPAD access needed - URGENT Good morning, We recently had a major ice storm and I need immediate emergency access for RACPAD to be granted to Ron Laney EID 31093 for stores 2974 and 3713. He will need SM access and for as long as we can grant it. Thank You, | J13: RACPad Support | K13: M0497 - - M0497 - R0039 - S07 - RTO | N13: PRB0045218 | O13: Incident | P13: Access | Q13: RACPAD Access not available
A14: INCTEC1581643 | B14: 3 - Moderate | C14: 46029.375 | D14: 46033.75 | E14: Closed | F14: monisha d | G14: RACPAD - Store | H14: Lost access to all her stores in RACPAD. Her stores should mirror Matt Dee, District Manager of District 480 | I14: Lost access to all her stores in RACPAD. Her stores should mirror Matt Dee, District Manager of District 480 | J14: RACPad Support | K14: M0480 - N/A - M0480 - R0007 - S08 - RTO | N14: PRB0045218 | O14: Incident | P14: Access | Q14: RACPAD Access not available
A15: INCTEC1581640 | B15: 3 - Moderate | C15: 46029.371 | D15: 46033.708 | E15: Closed | F15: Vandana K | G15: RACPAD - Store | H15: Lost access to all his stores in RACPAD | I15: Matt Dee has lost access to all his stores in RACPAD. | J15: RACPad Support | K15: M0480 - N/A - M0480 - R0007 - S08 - RTO | N15: PRB0045218 | O15: Incident | P15: Access | Q15: RACPAD Access not available
... A58: INCTEC1584577 | B58: 4 - Low | C58: 46036.514 | D58: 46045.417 | E58: Closed | F58: monisha d | G58: RACPAD - Store | H58: RACPAD - Store | RACPAD - Daily activity planner | | I58: On the goals tab of Daily Activity Planner, 1.the Actual & Variance are incorrect for all employees 2.Kaosoreal Washington should be removed from store 684 he doesn't work in my location 3. please Add Bradley King EID:132307 4. Add Bailey Bennett EID:100717 | J58: RACPad Support | K58: 00684 - ANCHORAGE-OLD SEWARD - A - M0414 - R0050 - S07 - RACUSA | N58: PRB0045218 | O58: Incident | P58: Access | Q58: RACPAD Access not available
A59: INCTEC1589368 | B59: 4 - Low | C59: 46048.435 | D59: 46053.417 | E59: Closed | F59: monisha d | G59: RACPAD - Store | H59: RACPAD - Store | RACPAD Store issue | | I59: I have signed out of everything multiple times and signed back in and it says I am not assigned to a store in RACPad ======================================================================= Co-worker name: Aaron Ingle Employee ID: 223270 Store: 02043 Issue: CW mentioned he is unable to login RACPAD. Getting error message. Need help with this. | J59: RACPad Support | K59: 02043 - 39TH & MACARTHUR - A - M0542 - R0080 - S08 - RACUSA | M59: CHG0050496 | N59: PRB0045218 | O59: Incident | P59: Access | Q59: RACPAD Access not available
A60: INCTEC1585553 | B60: 4 - Low | C60: 46038.56 | D60: 46048.375 | E60: Closed | F60: SatyaMurthy Dharmavarapu | G60: RACPAD - Store | H60: RACPAD - Store | RACPAD Store issue | | I60: I use to work for store 2621 in Brewer Maine and I now work for the store in Bangor Maine and I can still see there information and I was hoping to get that taken off. | J60: RACPad Support | K60: 00925 - BANGOR - A - M0272 - R0065 - S08 - RACUSA | N60: PRB0045218 | O60: Incident | P60: Access | Q60: RACPAD Access not available
A61: INCTEC1590334 | B61: 4 - Low | C61: 46050.449 | D61: 46059.125 | E61: Closed | F61: Vandana K | G61: RACPAD - Store | H61: RACPAD - Store | RACPAD Store issue | | I61: employee treyvon overstreet EID 330256 can still log into the wrong location and is unable to load any reports for store 01880 | J61: RACPad Support | K61: 01880 - AUBURN - A - M0314 - R0002 - S07 - RACUSA | N61: PRB0045218 | O61: Incident | P61: Access | Q61: RACPAD Access not available
A62: INCTEC1581646 | B62: 4 - Low | C62: 46029.378 | D62: 46044.5 | E62: Closed | F62: roopesh pothodi | G62: RACPAD - Store | H62: RACPAD - Store | RACPAD Store issue | | I62: Unable to login on any computer. My store info doesn't show. I've restarted every and tried logging into another profile.. Same results. Employee Name Bryce Robinson EID 369748 Store 02447 | J62: RACPad Support | K62: 02447 - CHESAPEAKE - A - M0007 - R0007 - S08 - RACUSA | N62: PRB0045218 | O62: Incident | P62: Access | Q62: RACPAD Access not available
A63: INCTEC1581425 | B63: 4 - Low | C63: 46028.662 | D63: 46034.375 | E63: Closed | F63: racha sahithya | G63: RACPAD - Store | H63: RACPAD - Store | The application is temporarily unavailable | | I63: Issue Description: CW reported that his RACPad only displays Account Management and is not attached to any store. No other options are available. This issue is not occurring for other coworkers at the same location. Employee Name: David Santiago2 Employee ID: 369651 Store: 04478 | J63: RACPad Support | K63: 04478 - CATSKILL-CATSKILL COMMON - A - M0444 - R0002 - S07 - RACUSA | N63: PRB0045218 | O63: Incident | P63: Access | Q63: RACPAD Access not available
A64: INCTEC1589552 | B64: 4 - Low | C64: 46048.606 | D64: 46054.75 | E64: Closed | F64: dazel dsouza | G64: RACPAD - Account Management | H64: RACPAD - Account Management | Worked History | | I64: A number of accounts have field visits being logged by an associate at another store on customers who are not min but are showing up on my AM activity log. The associate logging the visits is Amarion Lock. I do not know this employee. Customer ID: 00000 Customer Name: Lydia TRUJILLO Date and Time Issue Was Occured: 2026-01-26 14:16:36 | J64: RACPad Support | K64: 01238 - TAMPA-EAST - A - M0543 - R0024 - S08 - RACUSA | N64: PRB0045218 | O64: Incident | P64: Access | Q64: RACPAD Access not available
A65: INCTEC1587341 | B65: 4 - Low | C65: 46042.808 | D65: 46050.208 | E65: Closed | F65: Rashmitha Shetty | G65: RACPAD - Dashboard | H65: RACPAD - Dashboard | Dashboard - Other | | I65: Name: Ryan Looman EID: 361770 Store: 02034 Issue description: getting error messages when logging in. | J65: RACPad Support | K65: 02034 - CLASSEN - A - M0542 - R0080 - S08 - RACUSA | N65: PRB0045218 | O65: Incident | P65: Access | Q65: RACPAD Access not available
A66: INCTEC1590518 | B66: 4 - Low | C66: 46050.751 | D66: 46055.208 | E66: Closed | F66: Vandana K | G66: RACPAD - Dashboard | H66: RACPAD - Dashboard | Dashboard - Other | | I66: issue signing in, image pop up ever time. | J66: RACPad Support | K66: 02034 - CLASSEN - A - M0542 - R0080 - S08 - RACUSA | N66: PRB0045218 | O66: Incident | P66: Access | Q66: RACPAD Access not available
A67: INCTEC1588923 | B67: 4 - Low | C67: 46046.536 | D67: 46054.875 | E67: Closed | F67: monisha d | G67: RACPAD - Dashboard | H67: RACPAD - Dashboard | Dashboard - Other | | I67: Collin Thompson cant not get into racpad at all, it goes to an error screen ================================================================ Co-worker name: Collin Thompson2 Employee ID: 101014 Store: 00974 Issue: CW mentioned he is unable to login RACPAD. Getting error message. Need help with this. | J67: RACPad Support | K67: 00974 - POCATELLO - A - M0333 - R0050 - S07 - RACUSA | M67: CHG0050496 | N67: PRB0045218 | O67: Incident | P67: Access | Q67: RACPAD Access not available
A68: INCTEC1581138 | B68: 4 - Low | C68: 46028.36 | D68: 46034.417 | E68: Closed | F68: roopesh pothodi | G68: RACPAD - Dashboard | H68: RACPAD - Incorrect Store Login in RACPAD | I68: Store number: 00362 Coworker name and ID: Michael Velazquez (365222) Issue description: In RACPAD, Coworker reported being logged into store 00027 instead of the correct store 00362. Screen shot required: YES | J68: RACPad Support | K68: 00362 - CLEVELAND-WEST TOWN - A - M0196 - R0061 - S08 - RACUSA | N68: PRB0045218 | O68: Incident | P68: Access | Q68: RACPAD Access not available
A69: INCTEC1579643 | B69: 4 - Low | C69: 46024.58 | D69: 46033.375 | E69: Closed | F69: roopesh pothodi | G69: RACPAD - other | H69: RACPAD - other | I69: I'm the Store Manager at 4366 and I can't do extension on any customer account and I need to be able to give extension to my good paying customers that need help on ther accounts. Employee name- Charlie Gray Employee id - 188479 Store- 04366 | J69: RACPad Support | K69: 04366 - HATTIESBURG-BROADWAY - A - M0084 - R0008 - S07 - RACUSA | N69: PRB0045218 | O69: Incident | P69: Access | Q69: RACPAD Access not available
A70: INCTEC1588076 | B70: 4 - Low | C70: 46044.54 | D70: 46053.292 | E70: Closed | F70: Tejas Acharya | G70: RACPAD - other | H70: RACPAD - other | RACPAD Owner Config | | I70: Cannot log into Racpad Employee name- Lee Cain Employee id - 361130 Store- 00639 | J70: RACPad Support | K70: 00639 - CEDAR TOWN-MAIN - A - M0045 - R0070 - S08 - RACUSA | N70: PRB0045218 | O70: Incident | P70: Access | Q70: RACPAD Access not available
A71: INCTEC1579907 | B71: 4 - Low | C71: 46025.357 | D71: 46032.5 | E71: Closed | F71: Vandana K | G71: RACPAD - other | H71: RACFI-RACPAD - other | RACPAD Owner Config | | I71: Kirby Smith is not on it and he can't sign in. Employee name: Kirby Smith EMPID: 6020961 Store: 03553 Title: Store Manager-In Training Issue: Unable to access RACPAD app. | J71: RACPad Support | K71: 03553 - WILMINGTON-ROMBACH - A - M0510 - R0997 - S091 - RACFI | N71: PRB0045218 | O71: Incident | P71: Access | Q71: RACPAD access not available
A72: INCTEC1582004 | B72: 4 - Low | C72: 46030.358 | D72: 46038.292 | E72: Closed | F72: Tejas Acharya | G72: RACPAD - other | H72: RACFI-RACPAD - other | RACPAD Owner Config | | I72: When accessing the Racpad page he gts an error : I'm sorry but you currently don't have the necessary permissions to access this page. Please contact an administrator if you feel this is an error. | J72: RACPad Support | K72: 07237 - - A - M7017 - R0708 - S712 - RACFI | N72: PRB0045218 | O72: Incident | P72: Access | Q72: RACPAD access not available
A73: INCTEC1587977 | B73: 4 - Low | C73: 46044.448 | D73: 46053.292 | E73: Closed | F73: Tejas Acharya | G73: RACPAD - other | H73: RACPAD - other | RACPAD Owner Config | | I73: Anthony Warrington EID:100874 can not log into rac pad says admin error | J73: RACPad Support | K73: 00429 - EUSTIS - A - M0132 - R0024 - S08 - RACUSA | N73: PRB0045218 | O73: Incident | P73: Access | Q73: RACPAD Access not available
A74: INCTEC1589842 | B74: 4 - Low | C74: 46049.379 | D74: 46058.75 | E74: Closed | F74: Pratik Singar | G74: RACPAD - other | H74: RACPAD - other | RACPAD Owner Config | | I74: CW Name: Damien LanhamKeister Emp ID:370120 Store:00417 Description of issue: Can't login to RACPAD cw is getting an error | J74: RACPad Support | K74: 00417 - ASHEVILLE-PATTON - A - M0480 - R0007 - S08 - RACUSA | N74: PRB0045218 | O74: Incident | P74: Access | Q74: RACPAD Access not available
A75: INCTEC1589837 | B75: 4 - Low | C75: 46049.377 | D75: 46054.417 | E75: Closed | F75: Abhishek TV | G75: RACPAD - other | H75: RACPAD - other | RACPAD Owner Config | | I75: Will not allow me to login User: Nick Blackwelder EMP ID: 368485 Store: 00417 | J75: RACPad Support | K75: 00417 - ASHEVILLE-PATTON - A - M0480 - R0007 - S08 - RACUSA | N75: PRB0045218 | O75: Incident | P75: Access | Q75: RACPAD Access not available
A76: INCTEC1587619 | B76: 4 - Low | C76: 46043.527 | D76: 46051.333 | E76: Closed | F76: monisha d | G76: RACPAD - other | H76: RACPAD - other | RACPAD Owner Config | | I76: Tony Doll ( owner of Doble Inc.) cannot log into RACPAD. He is getting a message that he does not have permission. Could we please call and get it fixed? This is causing him issues with pricing rentals! ========================================================= Co-worker name: Tony Doll Employee ID: 313296 Store: R0704 Issue: CW mentioned he is unable to login RACPAD. Getting error message. Need help with this. | J76: RACPad Support | K76: R0704 - - R0704 - S707 - FRC | N76: PRB0045218 | O76: Incident | P76: Access | Q76: RACPAD Access not available
A77: INCTEC1581287 | B77: 4 - Low | C77: 46028.487 | D77: 46034.458 | E77: Closed | F77: Tejas Acharya | G77: RACPAD - other | H77: RACPAD - other | RACPAD Owner Config | | I77: RacPad does not show that I am in any store location --------------------------------- Emp name: Freddie WalterGates Emp id: 369688 Store number:02041 Issue: No Stores are assigned to the user in Racpad Error snapshot is attached | J77: RACPad Support | K77: 02041 - PEORIA - A - M0422 - R0080 - S08 - RACUSA | N77: PRB0045218 | O77: Incident | P77: Access | Q77: RACPAD Access not available
A78: INCTEC1587437 | B78: 3 - Moderate | C78: 46043.32 | D78: 46052.542 | E78: Closed | F78: roopesh pothodi | G78: RACPAD - other | H78: RACPAD - other | RACPAD Owner Config | | I78: I cannot get in RACPAD at all. Says I don't have permission. See screen shot. | J78: RACPad Support | K78: R0995 - - R0995 - S095 - FRC | N78: PRB0045218 | O78: Incident | P78: Access | Q78: RACPAD Access not available
A79: INCTEC1583939 | B79: 4 - Low | C79: 46035.317 | D79: 46047.208 | E79: Closed | F79: Sushmitha Sannidhi | G79: RACPAD - Dashboard | H79: RACPAD - Sales Person Tab – Coworker Name Not Visible | I79: Store number: 04495 Coworker name and ID: Nathan Cavers (350093) Issue description: While creating agreement coworker's name is not visible in Sales Person tab to select his name. Screen shot required: YES | J79: RACPad Support | K79: 04495 - MEDINA-MAIN - A - M0434 - R0058 - S08 - RACUSA | N79: PRB0045218 | O79: Incident | P79: Access | Q79: RACPAD Access not available
... A113: INCTEC1585398 | B113: 4 - Low | C113: 46038.414 | D113: 46046.208 | E113: Closed | F113: Tejas Acharya | G113: RACPAD - Dashboard | H113: RACPAD-Login issue | I113: Store number: 02937 Coworker name and ID: James Cook3 || 100777 Computer name: 02937-3PSSH63 Issue description: RACPAD login issue Steps taken to arrive at problem: RACPAD Login Dashboard | J113: RACPad Support | K113: 02937 - CAMP BOWIE BLVD - A - M0060 - R0080 - S08 - RACUSA | N113: PRB0045218 | O113: Incident | P113: Access | Q113: RACPAD Access not available
A114: INCTEC1589518 | B114: 4 - Low | C114: 46048.565 | D114: 46053.417 | E114: Closed | F114: monisha d | G114: RACPAD - Store | H114: store 02329 - Coworker Access | I114: Good Morning, I have an employee who can see several store systems. His employee ID number is 3310009 and he can currently see store 00346 and store 02329 but he is only assigned to store 2329. Can you help me with this? | J114: RACPad Support | K114: 02329 - DENBIGH - A - M0007 - R0007 - S08 - RACUSA | M114: CHG0050496 | N114: PRB0045218 | O114: Incident | P114: Access | Q114: RACPAD Access not available
A115: INCTEC1586040 | B115: 4 - Low | C115: 46039.733 | D115: 46047.208 | E115: Closed | F115: Sushmitha Sannidhi | G115: RACiNET | H115: RACiNET | No access allowed | | I115: No access allowed i keep getting ERROR MESSAGE when trying to open racpad | J115: RACPad Support | K115: 02345 - WINCHESTER - A - M0288 - R0058 - S08 - RACUSA | N115: PRB0045218 | O115: Incident | P115: Access | Q115: RACPAD access not available
...

Sheet Inc Summary
A3: Row Labels | B3: Count of Number
A4: BigPanda | B4: 1439
A5: (blank) | B5: 1439
A6: Payment | B6: 305
A7: Access | B7: 253
A8: Inventory | B8: 236
A9: Customer | B9: 223
A10: Agreement | B10: 152
A11: Store | B11: 91
A12: Account Management | B12: 54
A13: Report | B13: 45
A14: Admin | B14: 31
A15: other | B15: 11
... A21: Grand Total | B21: 2873

Sheet Issue wise details
A1: Module | B1: Type Of Issue | D1: Type Of Issue | E1: No of Occurences | F1: Issue Description | G1: Time to close the tickets | H1: One time/Recurring | I1: Automation/Shift Left | J1: Problem associated? | K1: Problem ticket | L1: Remarks
A2: Agreement | B2: Unable to void agreement | D2: RACPAD Access not available | E2: =COUNTIF(B:B,D2) -> 316 | F2: Spike due to workday migration | H2: One time | I2: Problem Management | J2: Yes | K2: PRB0045218
A3: Access | B3: RACPAD Access not available | D3: PO removal | E3: =COUNTIF(B:B,D3) -> 102 | F3: Request for removal of Manual PO | H3: Recurring | I3: Shift left(Approval) | J3: Yes | K3: PRB0045846 | L3: Form has to be created to eliminate the manual effort to reduce time collecting details from Store and ticket should be directly routed to RACPAD DS team to do data fix.
A4: Access | B4: RACPAD Access not available | D4: AutoPay | E4: =COUNTIF(B:B,D4) -> 62 | F4: Issue due to change in customer phone number or customer might have un-enrolled | G4: 5 hours | H4: Recurring | I4: Partially associated with PRB | J4: Yes
A5: Access | B5: RACPAD Access not available | D5: Customer order missing | E5: =COUNTIF(B:B,D5) -> 40 | F5: This was due to a request to disable customer order for a franchise-CHG0050479 | H5: One time | J5: No
A6: Agreement | B6: Missing Customer agreements which was transfered from previous store | D6: Payment done but not reflecting in RACPAD | E6: =COUNTIF(B:B,D6) -> 39 | F6: Amount got deducted from customer account but not showing in RACPAD | G6: 4 hours | H6: Recurring | I6: Automation/chat bot | J6: No
A7: Inventory | B7: Inventory mismatch between RMS and RACPAD | D7: Report issue | E7: =COUNTIF(B:B,D7) -> 35 | F7: Report related discrepencies | H7: Recurring | J7: Yes
A8: Report | B8: Report issue | D8: Void the agreement and change the inventory status to idle | E8: =COUNTIF(B:B,D8) -> 29 | F8: Void the agreement and update the inventory status to Rent-ready | H8: Recurring | I8: Problem Management | J8: Yes | K8: PRB0045970
A9: Payment | B9: Short Payment | D9: Missing Promo code | E9: =COUNTIF(B:B,D9) -> 28 | F9: Promo codes were not appearing | H9: One time | J9: No
A10: Payment | B10: Pay Date not reflecting | D10: Payment reversal | E10: =COUNTIF(B:B,D10) -> 24 | F10: Request to reverse the payment | H10: Recurring | I10: Problem Management | J10: Yes | K10: PRB0044395
A11: Payment | B11: Reverse the retention | D11: Incorrect processing fee | E11: =COUNTIF(B:B,D11) -> 23 | F11: Caused due to a config change which was then reverted back | H11: One time | J11: No
A12: Inventory | B12: PO removal | D12: Salesperson dropdown issue | E12: =COUNTIF(B:B,D12) -> 22 | F12: The salesperson dropdown list either shows terminated employees or wont have current CW's | H12: One time | I12: Problem Management | J12: Yes | K12: PRB0045968
A13: Inventory | B13: PO removal | D13: Unable to create an Agreement | E13: =COUNTIF(B:B,D13) -> 21 | F13: CW unable to create an agreement | H13: One time | J13: No
A14: Inventory | B14: PO removal | D14: PIN reset | E14: =COUNTIF(B:B,D14) -> 21 | F14: CW asking to reset the PIN | G14: 30 mins | H14: Recurring | I14: Automation | J14: No
A15: Payment | B15: Customer paid but still appearing in past due list | D15: Change the Inventory status | E15: =COUNTIF(B:B,D15) -> 19 | F15: Request to change the inventory status | H15: Recurring | I15: Problem Management | J15: Yes | K15: PRB0045883
A16: Inventory | B16: PO removal | D16: Failed to perform Record check request | E16: =COUNTIF(B:B,D16) -> 15 | F16: Unable to perform Customer record check | H16: One time | J16: No
A17: Inventory | B17: PO removal | D17: Unable to fetch the data | E17: =COUNTIF(B:B,D17) -> 15 | F17: Drop downs not loading in Account management | H17: One time | J17: Yes
A18: Customer | B18: Sales lead issue | D18: Customer needs to be refunded | E18: =COUNTIF(B:B,D18) -> 15 | F18: Refund related issues | H18: Recurring | J18: Yes
A19: Customer | B19: Sales lead issue | D19: CW missing in Sales goal | E19: =COUNTIF(B:B,D19) -> 13 | F19: Missing CW names in sales goal section | H19: Recurring | J19: No
A20: Inventory | B20: PO removal | D20: Inventory status change | E20: =COUNTIF(B:B,D20) -> 13 | F20: Request to change the inventory status | H20: Recurring | I20: Problem Management | J20: Yes | K20: PRB0045196
A21: Customer | B21: Customer level issue. Unable to add furniture | D21: Unable to confirm delivery | E21: =COUNTIF(B:B,D21) -> 12 | F21: CW unable to confirm delivery. Most of the times this will be due to missing customer phone number | H21: Recurring | I21: training issue | J21: No | L21: Making Primary Phone number field mandatory for Old customers
A22: Payment | B22: Unable to refund Web deposit | D22: Need to remove LDW | E22: =COUNTIF(B:B,D22) -> 12 | F22: Remove LDW | H22: Recurring | I22: Problem Management | J22: Yes | K22: PRB0045449
A23: Payment | B23: Unable to refund Web deposit | D23: Unable to receive Purchase order, please try again later | E23: =COUNTIF(B:B,D23) -> 10 | F23: When store tried to receive PO, they get the error "Unable to receive Po, please try again later" | H23: Recurring | J23: No | L23: Price republish
A24: Inventory | B24: PO removal | D24: Switch out issue | E24: =COUNTIF(B:B,D24) -> 10 | F24: Agreement switch-out completed, but inventory remains in "Pending Switch Out" status. | H24: Recurring | I24: Problem Management | J24: Yes | K24: PRB0045906
A25: Inventory | B25: PO removal | D25: Missing Store for CW | E25: =COUNTIF(B:B,D25) -> 9 | F25: CW missing access to transferred store( Will be having access of previous store) | G25: 5 hours | H25: Recurring | I25: Automation
A26: Report | B26: Issue with Manager route | D26: Drop reconciliation issue | E26: =COUNTIF(B:B,D26) -> 8 | F26: Issue while performing drop reconciliation | H26: Recurring | J26: No
A27: Inventory | B27: PO removal | D27: Unable to take payment. Asking to confirm delivery | E27: =COUNTIF(B:B,D27) -> 8 | F27: Issue while taking payment | H27: Recurring | J27: No
A28: Inventory | B28: PO removal | D28: Payment reversal request | E28: =COUNTIF(B:B,D28) -> 8 | F28: Payment reversal request | H28: Recurring | J28: Yes | K28: PRB0044395
A29: Report | B29: Issue with Manager route | D29: Customer level change request | E29: =COUNTIF(B:B,D29) -> 7 | F29: Request to change the level of the customer | H29: Recurring | I29: training issue | J29: No | L29: Form has to be created to eliminate the manual effort to reduce time collecting details from Store and ticket should be directly routed to Operations team for address these requests.
A30: Customer | B30: Unable to save customer details | D30: Welcome Video | E30: =COUNTIF(B:B,D30) -> 7 | F30: Caused due to a deployment | H30: One time | J30: No
A31: Inventory | B31: PO removal | D31: Wrong SAC | E31: =COUNTIF(B:B,D31) -> 7 | F31: Issue with SAC amount/date | H31: Recurring | J31: No
A32: Customer | B32: Unable to save customer details | D32: Promo code issue | E32: =COUNTIF(B:B,D32) -> 7 | F32: Issue with Promo code | H32: One time | J32: No
A33: Customer | B33: Approval level not appearing | D33: Intellicheck issue | E33: =COUNTIF(B:B,D33) -> 6
A34: Payment | B34: AutoPay | D34: Unable to return the agreement | E34: =COUNTIF(B:B,D34) -> 6
A35: Inventory | B35: PO removal | D35: Adjust the SAC amount | E35: =COUNTIF(B:B,D35) -> 6
A36: Inventory | B36: PO removal | D36: Unable to refund Web deposit | E36: =COUNTIF(B:B,D36) -> 5
A37: Payment | B37: AutoPay | D37: Customer level enquiry | E37: =COUNTIF(B:B,D37) -> 5
A38: Inventory | B38: PO removal | D38: Duplicate ticket | E38: =COUNTIF(B:B,D38) -> 5
A39: Inventory | B39: PO removal | D39: Customer charged twice | E39: =COUNTIF(B:B,D39) -> 5
A40: Inventory | B40: PO removal | D40: Item delivered but still showing as Pending | E40: =COUNTIF(B:B,D40) -> 5
...

Sheet Sheet7
A1: Problem id
A2: PRB0045218
A3: PRB0045846
A4: PRB0044727
A5: PRB0045970
A6: PRB0044829
A7: PRB0044395
A8: PRB0045455
A9: PRB0045968
A10: PRB0045883
A11: PRB0045473
A12: PRB0044947
... A81: PRB0045723

Sheet Sheet8
A1: Problem
A2: PRB0045805 | B2: =VLOOKUP(A2,Sheet7!A:A,1,FALSE) -> #N/A
A3: PRB0046021 | B3: =VLOOKUP(A3,Sheet7!A:A,1,FALSE) -> #N/A
A4: PRB0046044 | B4: =VLOOKUP(A4,Sheet7!A:A,1,FALSE) -> #N/A
A5: PRB0046050 | B5: =VLOOKUP(A5,Sheet7!A:A,1,FALSE) -> #N/A
A6: PRB0046041 | B6: =VLOOKUP(A6,Sheet7!A:A,1,FALSE) -> #N/A
A7: PRB0044564 | B7: =VLOOKUP(A7,Sheet7!A:A,1,FALSE) -> PRB0044564
A8: PRB0045499 | B8: =VLOOKUP(A8,Sheet7!A:A,1,FALSE) -> #N/A
A9: PRB0045695 | B9: =VLOOKUP(A9,Sheet7!A:A,1,FALSE) -> PRB0045695
A10: PRB0045802 | B10: =VLOOKUP(A10,Sheet7!A:A,1,FALSE) -> #N/A
A11: PRB0045373 | B11: =VLOOKUP(A11,Sheet7!A:A,1,FALSE) -> #N/A
A12: PRB0045824 | B12: =VLOOKUP(A12,Sheet7!A:A,1,FALSE) -> #N/A
A13: PRB0045280 | B13: =VLOOKUP(A13,Sheet7!A:A,1,FALSE) -> PRB0045280
... A16: PRB0045565 | B16: =VLOOKUP(A16,Sheet7!A:A,1,FALSE) -> PRB0045565
